Workbook

Sheet 근무표(입력)
A1: 근무일자 | B1: 요일 | C1: 타임1 | G1: 타임2 | K1: 타임3 | O1: 타임4 | S1: 타임5 | Y1: [ 개인별 근무 집계 현황 ]
C2: 이름 | D2: 출근 | E2: 퇴근 | F2: 시간 | G2: 이름 | H2: 출근 | I2: 퇴근 | J2: 시간 | K2: 이름 | L2: 출근 | M2: 퇴근 | N2: 시간 | O2: 이름 | P2: 출근 | Q2: 퇴근 | R2: 시간 | S2: 이름 | T2: 출근 | U2: 퇴근 | V2: 시간 | Y2: 이 름 | Z2: 총 근무시간 | AA2: 총 근무일수 | AN2: 주차(Hidden)
A3: 46054 | B3: =TEXT(A3, "aaa") -> 일 | F3: =IF(OR(D3="", E3=""), "", MOD(E3-D3,1)*24 - IF(MOD(E3-D3,1)*24 >= 8, 1, IF(MOD(E3-D3,1)*24 >= 4, 0.5, 0))) | J3: =IF(OR(H3="", I3=""), "", MOD(I3-H3,1)*24 - IF(MOD(I3-H3,1)*24 >= 8, 1, IF(MOD(I3-H3,1)*24 >= 4, 0.5, 0))) | N3: =IF(OR(L3="", M3=""), "", MOD(M3-L3,1)*24 - IF(MOD(M3-L3,1)*24 >= 8, 1, IF(MOD(M3-L3,1)*24 >= 4, 0.5, 0))) | R3: =IF(OR(P3="", Q3=""), "", MOD(Q3-P3,1)*24 - IF(MOD(Q3-P3,1)*24 >= 8, 1, IF(MOD(Q3-P3,1)*24 >= 4, 0.5, 0))) | V3: =IF(OR(T3="", U3=""), "", MOD(U3-T3,1)*24 - IF(MOD(U3-T3,1)*24 >= 8, 1, IF(MOD(U3-T3,1)*24 >= 4, 0.5, 0))) | X3: 1 | Y3: 김도윤 | Z3: =SUMIF($C$3:$C$33, $Y3, $F$3:$F$33)+SUMIF($G$3:$G$33, $Y3, $J$3:$J$33)+SUMIF($K$3:$K$33, $Y3, $N$3:$N$33)+SUMIF($S$3:$S$33, $Y3, $V$3:$V$33)+SUMIF($O$3:$O$33, $Y3, $R$3:$R$33) -> 0 | AA3: =COUNTIF($C$3:$C$33, $Y3) + COUNTIF($G$3:$G$33, $Y3) + COUNTIF($K$3:$K$33, $Y3) + COUNTIF($S$3:$S$33, $Y3)+ COUNTIF($O$3:$O$33, $Y3) -> 0 | AN3: =IF(A3="", 0, WEEKNUM(A3, 2)) -> 5
A4: =IF(A3="","",IF(MONTH(A3+1)<>MONTH($A$3),"",A3+1)) -> 46055 | B4: =IF(A4="","",TEXT(A4, "aaa")) -> 월 | F4: =IF(OR(D4="", E4=""), "", MOD(E4-D4,1)*24 - IF(MOD(E4-D4,1)*24 >= 8, 1, IF(MOD(E4-D4,1)*24 >= 4, 0.5, 0))) | J4: =IF(OR(H4="", I4=""), "", MOD(I4-H4,1)*24 - IF(MOD(I4-H4,1)*24 >= 8, 1, IF(MOD(I4-H4,1)*24 >= 4, 0.5, 0))) | N4: =IF(OR(L4="", M4=""), "", MOD(M4-L4,1)*24 - IF(MOD(M4-L4,1)*24 >= 8, 1, IF(MOD(M4-L4,1)*24 >= 4, 0.5, 0))) | R4: =IF(OR(P4="", Q4=""), "", MOD(Q4-P4,1)*24 - IF(MOD(Q4-P4,1)*24 >= 8, 1, IF(MOD(Q4-P4,1)*24 >= 4, 0.5, 0))) | V4: =IF(OR(T4="", U4=""), "", MOD(U4-T4,1)*24 - IF(MOD(U4-T4,1)*24 >= 8, 1, IF(MOD(U4-T4,1)*24 >= 4, 0.5, 0))) | X4: 2 | Y4: 김지수 | Z4: =SUMIF($C$3:$C$33, $Y4, $F$3:$F$33)+SUMIF($G$3:$G$33, $Y4, $J$3:$J$33)+SUMIF($K$3:$K$33, $Y4, $N$3:$N$33)+SUMIF($S$3:$S$33, $Y4, $V$3:$V$33)+SUMIF($O$3:$O$33, $Y4, $R$3:$R$33) -> 0 | AA4: =COUNTIF($C$3:$C$33, $Y4) + COUNTIF($G$3:$G$33, $Y4) + COUNTIF($K$3:$K$33, $Y4) + COUNTIF($S$3:$S$33, $Y4)+ COUNTIF($O$3:$O$33, $Y4) -> 0 | AN4: =IF(A4="", 0, WEEKNUM(A4, 2)) -> 6
A5: =IF(A4="","",IF(MONTH(A4+1)<>MONTH($A$3),"",A4+1)) -> 46056 | B5: =IF(A5="","",TEXT(A5, "aaa")) -> 화 | F5: =IF(OR(D5="", E5=""), "", MOD(E5-D5,1)*24 - IF(MOD(E5-D5,1)*24 >= 8, 1, IF(MOD(E5-D5,1)*24 >= 4, 0.5, 0))) | J5: =IF(OR(H5="", I5=""), "", MOD(I5-H5,1)*24 - IF(MOD(I5-H5,1)*24 >= 8, 1, IF(MOD(I5-H5,1)*24 >= 4, 0.5, 0))) | N5: =IF(OR(L5="", M5=""), "", MOD(M5-L5,1)*24 - IF(MOD(M5-L5,1)*24 >= 8, 1, IF(MOD(M5-L5,1)*24 >= 4, 0.5, 0))) | R5: =IF(OR(P5="", Q5=""), "", MOD(Q5-P5,1)*24 - IF(MOD(Q5-P5,1)*24 >= 8, 1, IF(MOD(Q5-P5,1)*24 >= 4, 0.5, 0))) | V5: =IF(OR(T5="", U5=""), "", MOD(U5-T5,1)*24 - IF(MOD(U5-T5,1)*24 >= 8, 1, IF(MOD(U5-T5,1)*24 >= 4, 0.5, 0))) | X5: 3 | Y5: 김현호 | Z5: =SUMIF($C$3:$C$33, $Y5, $F$3:$F$33)+SUMIF($G$3:$G$33, $Y5, $J$3:$J$33)+SUMIF($K$3:$K$33, $Y5, $N$3:$N$33)+SUMIF($S$3:$S$33, $Y5, $V$3:$V$33)+SUMIF($O$3:$O$33, $Y5, $R$3:$R$33) -> 0 | AA5: =COUNTIF($C$3:$C$33, $Y5) + COUNTIF($G$3:$G$33, $Y5) + COUNTIF($K$3:$K$33, $Y5) + COUNTIF($S$3:$S$33, $Y5)+ COUNTIF($O$3:$O$33, $Y5) -> 0 | AN5: =IF(A5="", 0, WEEKNUM(A5, 2)) -> 6
A6: =IF(A5="","",IF(MONTH(A5+1)<>MONTH($A$3),"",A5+1)) -> 46057 | B6: =IF(A6="","",TEXT(A6, "aaa")) -> 수 | F6: =IF(OR(D6="", E6=""), "", MOD(E6-D6,1)*24 - IF(MOD(E6-D6,1)*24 >= 8, 1, IF(MOD(E6-D6,1)*24 >= 4, 0.5, 0))) | J6: =IF(OR(H6="", I6=""), "", MOD(I6-H6,1)*24 - IF(MOD(I6-H6,1)*24 >= 8, 1, IF(MOD(I6-H6,1)*24 >= 4, 0.5, 0))) | N6: =IF(OR(L6="", M6=""), "", MOD(M6-L6,1)*24 - IF(MOD(M6-L6,1)*24 >= 8, 1, IF(MOD(M6-L6,1)*24 >= 4, 0.5, 0))) | R6: =IF(OR(P6="", Q6=""), "", MOD(Q6-P6,1)*24 - IF(MOD(Q6-P6,1)*24 >= 8, 1, IF(MOD(Q6-P6,1)*24 >= 4, 0.5, 0))) | V6: =IF(OR(T6="", U6=""), "", MOD(U6-T6,1)*24 - IF(MOD(U6-T6,1)*24 >= 8, 1, IF(MOD(U6-T6,1)*24 >= 4, 0.5, 0))) | X6: 4 | Y6: 송채민 | Z6: =SUMIF($C$3:$C$33, $Y6, $F$3:$F$33)+SUMIF($G$3:$G$33, $Y6, $J$3:$J$33)+SUMIF($K$3:$K$33, $Y6, $N$3:$N$33)+SUMIF($S$3:$S$33, $Y6, $V$3:$V$33)+SUMIF($O$3:$O$33, $Y6, $R$3:$R$33) -> 0 | AA6: =COUNTIF($C$3:$C$33, $Y6) + COUNTIF($G$3:$G$33, $Y6) + COUNTIF($K$3:$K$33, $Y6) + COUNTIF($S$3:$S$33, $Y6)+ COUNTIF($O$3:$O$33, $Y6) -> 0 | AN6: =IF(A6="", 0, WEEKNUM(A6, 2)) -> 6
A7: =IF(A6="","",IF(MONTH(A6+1)<>MONTH($A$3),"",A6+1)) -> 46058 | B7: =IF(A7="","",TEXT(A7, "aaa")) -> 목 | F7: =IF(OR(D7="", E7=""), "", MOD(E7-D7,1)*24 - IF(MOD(E7-D7,1)*24 >= 8, 1, IF(MOD(E7-D7,1)*24 >= 4, 0.5, 0))) | J7: =IF(OR(H7="", I7=""), "", MOD(I7-H7,1)*24 - IF(MOD(I7-H7,1)*24 >= 8, 1, IF(MOD(I7-H7,1)*24 >= 4, 0.5, 0))) | N7: =IF(OR(L7="", M7=""), "", MOD(M7-L7,1)*24 - IF(MOD(M7-L7,1)*24 >= 8, 1, IF(MOD(M7-L7,1)*24 >= 4, 0.5, 0))) | R7: =IF(OR(P7="", Q7=""), "", MOD(Q7-P7,1)*24 - IF(MOD(Q7-P7,1)*24 >= 8, 1, IF(MOD(Q7-P7,1)*24 >= 4, 0.5, 0))) | V7: =IF(OR(T7="", U7=""), "", MOD(U7-T7,1)*24 - IF(MOD(U7-T7,1)*24 >= 8, 1, IF(MOD(U7-T7,1)*24 >= 4, 0.5, 0))) | X7: 5 | Y7: 이예은 | Z7: =SUMIF($C$3:$C$33, $Y7, $F$3:$F$33)+SUMIF($G$3:$G$33, $Y7, $J$3:$J$33)+SUMIF($K$3:$K$33, $Y7, $N$3:$N$33)+SUMIF($S$3:$S$33, $Y7, $V$3:$V$33)+SUMIF($O$3:$O$33, $Y7, $R$3:$R$33) -> 0 | AA7: =COUNTIF($C$3:$C$33, $Y7) + COUNTIF($G$3:$G$33, $Y7) + COUNTIF($K$3:$K$33, $Y7) + COUNTIF($S$3:$S$33, $Y7)+ COUNTIF($O$3:$O$33, $Y7) -> 0 | AN7: =IF(A7="", 0, WEEKNUM(A7, 2)) -> 6
A8: =IF(A7="","",IF(MONTH(A7+1)<>MONTH($A$3),"",A7+1)) -> 46059 | B8: =IF(A8="","",TEXT(A8, "aaa")) -> 금 | F8: =IF(OR(D8="", E8=""), "", MOD(E8-D8,1)*24 - IF(MOD(E8-D8,1)*24 >= 8, 1, IF(MOD(E8-D8,1)*24 >= 4, 0.5, 0))) | J8: =IF(OR(H8="", I8=""), "", MOD(I8-H8,1)*24 - IF(MOD(I8-H8,1)*24 >= 8, 1, IF(MOD(I8-H8,1)*24 >= 4, 0.5, 0))) | N8: =IF(OR(L8="", M8=""), "", MOD(M8-L8,1)*24 - IF(MOD(M8-L8,1)*24 >= 8, 1, IF(MOD(M8-L8,1)*24 >= 4, 0.5, 0))) | R8: =IF(OR(P8="", Q8=""), "", MOD(Q8-P8,1)*24 - IF(MOD(Q8-P8,1)*24 >= 8, 1, IF(MOD(Q8-P8,1)*24 >= 4, 0.5, 0))) | V8: =IF(OR(T8="", U8=""), "", MOD(U8-T8,1)*24 - IF(MOD(U8-T8,1)*24 >= 8, 1, IF(MOD(U8-T8,1)*24 >= 4, 0.5, 0))) | X8: 6 | Y8: 정가은 | Z8: =SUMIF($C$3:$C$33, $Y8, $F$3:$F$33)+SUMIF($G$3:$G$33, $Y8, $J$3:$J$33)+SUMIF($K$3:$K$33, $Y8, $N$3:$N$33)+SUMIF($S$3:$S$33, $Y8, $V$3:$V$33)+SUMIF($O$3:$O$33, $Y8, $R$3:$R$33) -> 0 | AA8: =COUNTIF($C$3:$C$33, $Y8) + COUNTIF($G$3:$G$33, $Y8) + COUNTIF($K$3:$K$33, $Y8) + COUNTIF($S$3:$S$33, $Y8)+ COUNTIF($O$3:$O$33, $Y8) -> 0 | AN8: =IF(A8="", 0, WEEKNUM(A8, 2)) -> 6
A9: =IF(A8="","",IF(MONTH(A8+1)<>MONTH($A$3),"",A8+1)) -> 46060 | B9: =IF(A9="","",TEXT(A9, "aaa")) -> 토 | F9: =IF(OR(D9="", E9=""), "", MOD(E9-D9,1)*24 - IF(MOD(E9-D9,1)*24 >= 8, 1, IF(MOD(E9-D9,1)*24 >= 4, 0.5, 0))) | J9: =IF(OR(H9="", I9=""), "", MOD(I9-H9,1)*24 - IF(MOD(I9-H9,1)*24 >= 8, 1, IF(MOD(I9-H9,1)*24 >= 4, 0.5, 0))) | N9: =IF(OR(L9="", M9=""), "", MOD(M9-L9,1)*24 - IF(MOD(M9-L9,1)*24 >= 8, 1, IF(MOD(M9-L9,1)*24 >= 4, 0.5, 0))) | R9: =IF(OR(P9="", Q9=""), "", MOD(Q9-P9,1)*24 - IF(MOD(Q9-P9,1)*24 >= 8, 1, IF(MOD(Q9-P9,1)*24 >= 4, 0.5, 0))) | V9: =IF(OR(T9="", U9=""), "", MOD(U9-T9,1)*24 - IF(MOD(U9-T9,1)*24 >= 8, 1, IF(MOD(U9-T9,1)*24 >= 4, 0.5, 0))) | X9: 7 | Y9: 황승연 | Z9: =SUMIF($C$3:$C$33, $Y9, $F$3:$F$33)+SUMIF($G$3:$G$33, $Y9, $J$3:$J$33)+SUMIF($K$3:$K$33, $Y9, $N$3:$N$33)+SUMIF($S$3:$S$33, $Y9, $V$3:$V$33)+SUMIF($O$3:$O$33, $Y9, $R$3:$R$33) -> 0 | AA9: =COUNTIF($C$3:$C$33, $Y9) + COUNTIF($G$3:$G$33, $Y9) + COUNTIF($K$3:$K$33, $Y9) + COUNTIF($S$3:$S$33, $Y9)+ COUNTIF($O$3:$O$33, $Y9) -> 0 | AN9: =IF(A9="", 0, WEEKNUM(A9, 2)) -> 6
A10: =IF(A9="","",IF(MONTH(A9+1)<>MONTH($A$3),"",A9+1)) -> 46061 | B10: =IF(A10="","",TEXT(A10, "aaa")) -> 일 | F10: =IF(OR(D10="", E10=""), "", MOD(E10-D10,1)*24 - IF(MOD(E10-D10,1)*24 >= 8, 1, IF(MOD(E10-D10,1)*24 >= 4, 0.5, 0))) | J10: =IF(OR(H10="", I10=""), "", MOD(I10-H10,1)*24 - IF(MOD(I10-H10,1)*24 >= 8, 1, IF(MOD(I10-H10,1)*24 >= 4, 0.5, 0))) | N10: =IF(OR(L10="", M10=""), "", MOD(M10-L10,1)*24 - IF(MOD(M10-L10,1)*24 >= 8, 1, IF(MOD(M10-L10,1)*24 >= 4, 0.5, 0))) | R10: =IF(OR(P10="", Q10=""), "", MOD(Q10-P10,1)*24 - IF(MOD(Q10-P10,1)*24 >= 8, 1, IF(MOD(Q10-P10,1)*24 >= 4, 0.5, 0))) | V10: =IF(OR(T10="", U10=""), "", MOD(U10-T10,1)*24 - IF(MOD(U10-T10,1)*24 >= 8, 1, IF(MOD(U10-T10,1)*24 >= 4, 0.5, 0))) | X10: 8 | Z10: =SUMIF($C$3:$C$33, $Y10, $F$3:$F$33)+SUMIF($G$3:$G$33, $Y10, $J$3:$J$33)+SUMIF($K$3:$K$33, $Y10, $N$3:$N$33)+SUMIF($S$3:$S$33, $Y10, $V$3:$V$33)+SUMIF($O$3:$O$33, $Y10, $R$3:$R$33) -> 0 | AA10: =COUNTIF($C$3:$C$33, $Y10) + COUNTIF($G$3:$G$33, $Y10) + COUNTIF($K$3:$K$33, $Y10) + COUNTIF($S$3:$S$33, $Y10)+ COUNTIF($O$3:$O$33, $Y10) -> 0 | AN10: =IF(A10="", 0, WEEKNUM(A10, 2)) -> 6
A11: =IF(A10="","",IF(MONTH(A10+1)<>MONTH($A$3),"",A10+1)) -> 46062 | B11: =IF(A11="","",TEXT(A11, "aaa")) -> 월 | F11: =IF(OR(D11="", E11=""), "", MOD(E11-D11,1)*24 - IF(MOD(E11-D11,1)*24 >= 8, 1, IF(MOD(E11-D11,1)*24 >= 4, 0.5, 0))) | J11: =IF(OR(H11="", I11=""), "", MOD(I11-H11,1)*24 - IF(MOD(I11-H11,1)*24 >= 8, 1, IF(MOD(I11-H11,1)*24 >= 4, 0.5, 0))) | N11: =IF(OR(L11="", M11=""), "", MOD(M11-L11,1)*24 - IF(MOD(M11-L11,1)*24 >= 8, 1, IF(MOD(M11-L11,1)*24 >= 4, 0.5, 0))) | R11: =IF(OR(P11="", Q11=""), "", MOD(Q11-P11,1)*24 - IF(MOD(Q11-P11,1)*24 >= 8, 1, IF(MOD(Q11-P11,1)*24 >= 4, 0.5, 0))) | V11: =IF(OR(T11="", U11=""), "", MOD(U11-T11,1)*24 - IF(MOD(U11-T11,1)*24 >= 8, 1, IF(MOD(U11-T11,1)*24 >= 4, 0.5, 0))) | X11: 9 | Z11: =SUMIF($C$3:$C$33, $Y11, $F$3:$F$33)+SUMIF($G$3:$G$33, $Y11, $J$3:$J$33)+SUMIF($K$3:$K$33, $Y11, $N$3:$N$33)+SUMIF($S$3:$S$33, $Y11, $V$3:$V$33)+SUMIF($O$3:$O$33, $Y11, $R$3:$R$33) -> 0 | AA11: =COUNTIF($C$3:$C$33, $Y11) + COUNTIF($G$3:$G$33, $Y11) + COUNTIF($K$3:$K$33, $Y11) + COUNTIF($S$3:$S$33, $Y11)+ COUNTIF($O$3:$O$33, $Y11) -> 0 | AN11: =IF(A11="", 0, WEEKNUM(A11, 2)) -> 7
A12: =IF(A11="","",IF(MONTH(A11+1)<>MONTH($A$3),"",A11+1)) -> 46063 | B12: =IF(A12="","",TEXT(A12, "aaa")) -> 화 | F12: =IF(OR(D12="", E12=""), "", MOD(E12-D12,1)*24 - IF(MOD(E12-D12,1)*24 >= 8, 1, IF(MOD(E12-D12,1)*24 >= 4, 0.5, 0))) | J12: =IF(OR(H12="", I12=""), "", MOD(I12-H12,1)*24 - IF(MOD(I12-H12,1)*24 >= 8, 1, IF(MOD(I12-H12,1)*24 >= 4, 0.5, 0))) | N12: =IF(OR(L12="", M12=""), "", MOD(M12-L12,1)*24 - IF(MOD(M12-L12,1)*24 >= 8, 1, IF(MOD(M12-L12,1)*24 >= 4, 0.5, 0))) | R12: =IF(OR(P12="", Q12=""), "", MOD(Q12-P12,1)*24 - IF(MOD(Q12-P12,1)*24 >= 8, 1, IF(MOD(Q12-P12,1)*24 >= 4, 0.5, 0))) | V12: =IF(OR(T12="", U12=""), "", MOD(U12-T12,1)*24 - IF(MOD(U12-T12,1)*24 >= 8, 1, IF(MOD(U12-T12,1)*24 >= 4, 0.5, 0))) | X12: 10 | Z12: =SUMIF($C$3:$C$33, $Y12, $F$3:$F$33)+SUMIF($G$3:$G$33, $Y12, $J$3:$J$33)+SUMIF($K$3:$K$33, $Y12, $N$3:$N$33)+SUMIF($S$3:$S$33, $Y12, $V$3:$V$33)+SUMIF($O$3:$O$33, $Y12, $R$3:$R$33) -> 0 | AA12: =COUNTIF($C$3:$C$33, $Y12) + COUNTIF($G$3:$G$33, $Y12) + COUNTIF($K$3:$K$33, $Y12) + COUNTIF($S$3:$S$33, $Y12)+ COUNTIF($O$3:$O$33, $Y12) -> 0 | AN12: =IF(A12="", 0, WEEKNUM(A12, 2)) -> 7
A13: =IF(A12="","",IF(MONTH(A12+1)<>MONTH($A$3),"",A12+1)) -> 46064 | B13: =IF(A13="","",TEXT(A13, "aaa")) -> 수 | F13: =IF(OR(D13="", E13=""), "", MOD(E13-D13,1)*24 - IF(MOD(E13-D13,1)*24 >= 8, 1, IF(MOD(E13-D13,1)*24 >= 4, 0.5, 0))) | J13: =IF(OR(H13="", I13=""), "", MOD(I13-H13,1)*24 - IF(MOD(I13-H13,1)*24 >= 8, 1, IF(MOD(I13-H13,1)*24 >= 4, 0.5, 0))) | N13: =IF(OR(L13="", M13=""), "", MOD(M13-L13,1)*24 - IF(MOD(M13-L13,1)*24 >= 8, 1, IF(MOD(M13-L13,1)*24 >= 4, 0.5, 0))) | R13: =IF(OR(P13="", Q13=""), "", MOD(Q13-P13,1)*24 - IF(MOD(Q13-P13,1)*24 >= 8, 1, IF(MOD(Q13-P13,1)*24 >= 4, 0.5, 0))) | V13: =IF(OR(T13="", U13=""), "", MOD(U13-T13,1)*24 - IF(MOD(U13-T13,1)*24 >= 8, 1, IF(MOD(U13-T13,1)*24 >= 4, 0.5, 0))) | X13: 11 | Z13: =SUMIF($C$3:$C$33, $Y13, $F$3:$F$33)+SUMIF($G$3:$G$33, $Y13, $J$3:$J$33)+SUMIF($K$3:$K$33, $Y13, $N$3:$N$33)+SUMIF($S$3:$S$33, $Y13, $V$3:$V$33)+SUMIF($O$3:$O$33, $Y13, $R$3:$R$33) -> 0 | AA13: =COUNTIF($C$3:$C$33, $Y13) + COUNTIF($G$3:$G$33, $Y13) + COUNTIF($K$3:$K$33, $Y13) + COUNTIF($S$3:$S$33, $Y13)+ COUNTIF($O$3:$O$33, $Y13) -> 0 | AN13: =IF(A13="", 0, WEEKNUM(A13, 2)) -> 7
A14: =IF(A13="","",IF(MONTH(A13+1)<>MONTH($A$3),"",A13+1)) -> 46065 | B14: =IF(A14="","",TEXT(A14, "aaa")) -> 목 | F14: =IF(OR(D14="", E14=""), "", MOD(E14-D14,1)*24 - IF(MOD(E14-D14,1)*24 >= 8, 1, IF(MOD(E14-D14,1)*24 >= 4, 0.5, 0))) | J14: =IF(OR(H14="", I14=""), "", MOD(I14-H14,1)*24 - IF(MOD(I14-H14,1)*24 >= 8, 1, IF(MOD(I14-H14,1)*24 >= 4, 0.5, 0))) | N14: =IF(OR(L14="", M14=""), "", MOD(M14-L14,1)*24 - IF(MOD(M14-L14,1)*24 >= 8, 1, IF(MOD(M14-L14,1)*24 >= 4, 0.5, 0))) | R14: =IF(OR(P14="", Q14=""), "", MOD(Q14-P14,1)*24 - IF(MOD(Q14-P14,1)*24 >= 8, 1, IF(MOD(Q14-P14,1)*24 >= 4, 0.5, 0))) | V14: =IF(OR(T14="", U14=""), "", MOD(U14-T14,1)*24 - IF(MOD(U14-T14,1)*24 >= 8, 1, IF(MOD(U14-T14,1)*24 >= 4, 0.5, 0))) | X14: 12 | Z14: =SUMIF($C$3:$C$33, $Y14, $F$3:$F$33)+SUMIF($G$3:$G$33, $Y14, $J$3:$J$33)+SUMIF($K$3:$K$33, $Y14, $N$3:$N$33)+SUMIF($S$3:$S$33, $Y14, $V$3:$V$33)+SUMIF($O$3:$O$33, $Y14, $R$3:$R$33) -> 0 | AA14: =COUNTIF($C$3:$C$33, $Y14) + COUNTIF($G$3:$G$33, $Y14) + COUNTIF($K$3:$K$33, $Y14) + COUNTIF($S$3:$S$33, $Y14)+ COUNTIF($O$3:$O$33, $Y14) -> 0 | AN14: =IF(A14="", 0, WEEKNUM(A14, 2)) -> 7
A15: =IF(A14="","",IF(MONTH(A14+1)<>MONTH($A$3),"",A14+1)) -> 46066 | B15: =IF(A15="","",TEXT(A15, "aaa")) -> 금 | F15: =IF(OR(D15="", E15=""), "", MOD(E15-D15,1)*24 - IF(MOD(E15-D15,1)*24 >= 8, 1, IF(MOD(E15-D15,1)*24 >= 4, 0.5, 0))) | J15: =IF(OR(H15="", I15=""), "", MOD(I15-H15,1)*24 - IF(MOD(I15-H15,1)*24 >= 8, 1, IF(MOD(I15-H15,1)*24 >= 4, 0.5, 0))) | N15: =IF(OR(L15="", M15=""), "", MOD(M15-L15,1)*24 - IF(MOD(M15-L15,1)*24 >= 8, 1, IF(MOD(M15-L15,1)*24 >= 4, 0.5, 0))) | R15: =IF(OR(P15="", Q15=""), "", MOD(Q15-P15,1)*24 - IF(MOD(Q15-P15,1)*24 >= 8, 1, IF(MOD(Q15-P15,1)*24 >= 4, 0.5, 0))) | V15: =IF(OR(T15="", U15=""), "", MOD(U15-T15,1)*24 - IF(MOD(U15-T15,1)*24 >= 8, 1, IF(MOD(U15-T15,1)*24 >= 4, 0.5, 0))) | X15: 13 | Z15: =SUMIF($C$3:$C$33, $Y15, $F$3:$F$33)+SUMIF($G$3:$G$33, $Y15, $J$3:$J$33)+SUMIF($K$3:$K$33, $Y15, $N$3:$N$33)+SUMIF($S$3:$S$33, $Y15, $V$3:$V$33)+SUMIF($O$3:$O$33, $Y15, $R$3:$R$33) -> 0 | AA15: =COUNTIF($C$3:$C$33, $Y15) + COUNTIF($G$3:$G$33, $Y15) + COUNTIF($K$3:$K$33, $Y15) + COUNTIF($S$3:$S$33, $Y15)+ COUNTIF($O$3:$O$33, $Y15) -> 0 | AN15: =IF(A15="", 0, WEEKNUM(A15, 2)) -> 7
A16: =IF(A15="","",IF(MONTH(A15+1)<>MONTH($A$3),"",A15+1)) -> 46067 | B16: =IF(A16="","",TEXT(A16, "aaa")) -> 토 | F16: =IF(OR(D16="", E16=""), "", MOD(E16-D16,1)*24 - IF(MOD(E16-D16,1)*24 >= 8, 1, IF(MOD(E16-D16,1)*24 >= 4, 0.5, 0))) | J16: =IF(OR(H16="", I16=""), "", MOD(I16-H16,1)*24 - IF(MOD(I16-H16,1)*24 >= 8, 1, IF(MOD(I16-H16,1)*24 >= 4, 0.5, 0))) | N16: =IF(OR(L16="", M16=""), "", MOD(M16-L16,1)*24 - IF(MOD(M16-L16,1)*24 >= 8, 1, IF(MOD(M16-L16,1)*24 >= 4, 0.5, 0))) | R16: =IF(OR(P16="", Q16=""), "", MOD(Q16-P16,1)*24 - IF(MOD(Q16-P16,1)*24 >= 8, 1, IF(MOD(Q16-P16,1)*24 >= 4, 0.5, 0))) | V16: =IF(OR(T16="", U16=""), "", MOD(U16-T16,1)*24 - IF(MOD(U16-T16,1)*24 >= 8, 1, IF(MOD(U16-T16,1)*24 >= 4, 0.5, 0))) | X16: 14 | Z16: =SUMIF($C$3:$C$33, $Y16, $F$3:$F$33)+SUMIF($G$3:$G$33, $Y16, $J$3:$J$33)+SUMIF($K$3:$K$33, $Y16, $N$3:$N$33)+SUMIF($S$3:$S$33, $Y16, $V$3:$V$33)+SUMIF($O$3:$O$33, $Y16, $R$3:$R$33) -> 0 | AA16: =COUNTIF($C$3:$C$33, $Y16) + COUNTIF($G$3:$G$33, $Y16) + COUNTIF($K$3:$K$33, $Y16) + COUNTIF($S$3:$S$33, $Y16)+ COUNTIF($O$3:$O$33, $Y16) -> 0 | AN16: =IF(A16="", 0, WEEKNUM(A16, 2)) -> 7
A17: =IF(A16="","",IF(MONTH(A16+1)<>MONTH($A$3),"",A16+1)) -> 46068 | B17: =IF(A17="","",TEXT(A17, "aaa")) -> 일 | F17: =IF(OR(D17="", E17=""), "", MOD(E17-D17,1)*24 - IF(MOD(E17-D17,1)*24 >= 8, 1, IF(MOD(E17-D17,1)*24 >= 4, 0.5, 0))) | J17: =IF(OR(H17="", I17=""), "", MOD(I17-H17,1)*24 - IF(MOD(I17-H17,1)*24 >= 8, 1, IF(MOD(I17-H17,1)*24 >= 4, 0.5, 0))) | N17: =IF(OR(L17="", M17=""), "", MOD(M17-L17,1)*24 - IF(MOD(M17-L17,1)*24 >= 8, 1, IF(MOD(M17-L17,1)*24 >= 4, 0.5, 0))) | R17: =IF(OR(P17="", Q17=""), "", MOD(Q17-P17,1)*24 - IF(MOD(Q17-P17,1)*24 >= 8, 1, IF(MOD(Q17-P17,1)*24 >= 4, 0.5, 0))) | V17: =IF(OR(T17="", U17=""), "", MOD(U17-T17,1)*24 - IF(MOD(U17-T17,1)*24 >= 8, 1, IF(MOD(U17-T17,1)*24 >= 4, 0.5, 0))) | AN17: =IF(A17="", 0, WEEKNUM(A17, 2)) -> 7
A18: =IF(A17="","",IF(MONTH(A17+1)<>MONTH($A$3),"",A17+1)) -> 46069 | B18: =IF(A18="","",TEXT(A18, "aaa")) -> 월 | F18: =IF(OR(D18="", E18=""), "", MOD(E18-D18,1)*24 - IF(MOD(E18-D18,1)*24 >= 8, 1, IF(MOD(E18-D18,1)*24 >= 4, 0.5, 0))) | J18: =IF(OR(H18="", I18=""), "", MOD(I18-H18,1)*24 - IF(MOD(I18-H18,1)*24 >= 8, 1, IF(MOD(I18-H18,1)*24 >= 4, 0.5, 0))) | N18: =IF(OR(L18="", M18=""), "", MOD(M18-L18,1)*24 - IF(MOD(M18-L18,1)*24 >= 8, 1, IF(MOD(M18-L18,1)*24 >= 4, 0.5, 0))) | R18: =IF(OR(P18="", Q18=""), "", MOD(Q18-P18,1)*24 - IF(MOD(Q18-P18,1)*24 >= 8, 1, IF(MOD(Q18-P18,1)*24 >= 4, 0.5, 0))) | V18: =IF(OR(T18="", U18=""), "", MOD(U18-T18,1)*24 - IF(MOD(U18-T18,1)*24 >= 8, 1, IF(MOD(U18-T18,1)*24 >= 4, 0.5, 0))) | AN18: =IF(A18="", 0, WEEKNUM(A18, 2)) -> 8
A19: =IF(A18="","",IF(MONTH(A18+1)<>MONTH($A$3),"",A18+1)) -> 46070 | B19: =IF(A19="","",TEXT(A19, "aaa")) -> 화 | F19: =IF(OR(D19="", E19=""), "", MOD(E19-D19,1)*24 - IF(MOD(E19-D19,1)*24 >= 8, 1, IF(MOD(E19-D19,1)*24 >= 4, 0.5, 0))) | J19: =IF(OR(H19="", I19=""), "", MOD(I19-H19,1)*24 - IF(MOD(I19-H19,1)*24 >= 8, 1, IF(MOD(I19-H19,1)*24 >= 4, 0.5, 0))) | N19: =IF(OR(L19="", M19=""), "", MOD(M19-L19,1)*24 - IF(MOD(M19-L19,1)*24 >= 8, 1, IF(MOD(M19-L19,1)*24 >= 4, 0.5, 0))) | R19: =IF(OR(P19="", Q19=""), "", MOD(Q19-P19,1)*24 - IF(MOD(Q19-P19,1)*24 >= 8, 1, IF(MOD(Q19-P19,1)*24 >= 4, 0.5, 0))) | V19: =IF(OR(T19="", U19=""), "", MOD(U19-T19,1)*24 - IF(MOD(U19-T19,1)*24 >= 8, 1, IF(MOD(U19-T19,1)*24 >= 4, 0.5, 0))) | AN19: =IF(A19="", 0, WEEKNUM(A19, 2)) -> 8
A20: =IF(A19="","",IF(MONTH(A19+1)<>MONTH($A$3),"",A19+1)) -> 46071 | B20: =IF(A20="","",TEXT(A20, "aaa")) -> 수 | F20: =IF(OR(D20="", E20=""), "", MOD(E20-D20,1)*24 - IF(MOD(E20-D20,1)*24 >= 8, 1, IF(MOD(E20-D20,1)*24 >= 4, 0.5, 0))) | J20: =IF(OR(H20="", I20=""), "", MOD(I20-H20,1)*24 - IF(MOD(I20-H20,1)*24 >= 8, 1, IF(MOD(I20-H20,1)*24 >= 4, 0.5, 0))) | N20: =IF(OR(L20="", M20=""), "", MOD(M20-L20,1)*24 - IF(MOD(M20-L20,1)*24 >= 8, 1, IF(MOD(M20-L20,1)*24 >= 4, 0.5, 0))) | R20: =IF(OR(P20="", Q20=""), "", MOD(Q20-P20,1)*24 - IF(MOD(Q20-P20,1)*24 >= 8, 1, IF(MOD(Q20-P20,1)*24 >= 4, 0.5, 0))) | V20: =IF(OR(T20="", U20=""), "", MOD(U20-T20,1)*24 - IF(MOD(U20-T20,1)*24 >= 8, 1, IF(MOD(U20-T20,1)*24 >= 4, 0.5, 0))) | AN20: =IF(A20="", 0, WEEKNUM(A20, 2)) -> 8
A21: =IF(A20="","",IF(MONTH(A20+1)<>MONTH($A$3),"",A20+1)) -> 46072 | B21: =IF(A21="","",TEXT(A21, "aaa")) -> 목 | F21: =IF(OR(D21="", E21=""), "", MOD(E21-D21,1)*24 - IF(MOD(E21-D21,1)*24 >= 8, 1, IF(MOD(E21-D21,1)*24 >= 4, 0.5, 0))) | J21: =IF(OR(H21="", I21=""), "", MOD(I21-H21,1)*24 - IF(MOD(I21-H21,1)*24 >= 8, 1, IF(MOD(I21-H21,1)*24 >= 4, 0.5, 0))) | N21: =IF(OR(L21="", M21=""), "", MOD(M21-L21,1)*24 - IF(MOD(M21-L21,1)*24 >= 8, 1, IF(MOD(M21-L21,1)*24 >= 4, 0.5, 0))) | R21: =IF(OR(P21="", Q21=""), "", MOD(Q21-P21,1)*24 - IF(MOD(Q21-P21,1)*24 >= 8, 1, IF(MOD(Q21-P21,1)*24 >= 4, 0.5, 0))) | V21: =IF(OR(T21="", U21=""), "", MOD(U21-T21,1)*24 - IF(MOD(U21-T21,1)*24 >= 8, 1, IF(MOD(U21-T21,1)*24 >= 4, 0.5, 0))) | AN21: =IF(A21="", 0, WEEKNUM(A21, 2)) -> 8
A22: =IF(A21="","",IF(MONTH(A21+1)<>MONTH($A$3),"",A21+1)) -> 46073 | B22: =IF(A22="","",TEXT(A22, "aaa")) -> 금 | F22: =IF(OR(D22="", E22=""), "", MOD(E22-D22,1)*24 - IF(MOD(E22-D22,1)*24 >= 8, 1, IF(MOD(E22-D22,1)*24 >= 4, 0.5, 0))) | J22: =IF(OR(H22="", I22=""), "", MOD(I22-H22,1)*24 - IF(MOD(I22-H22,1)*24 >= 8, 1, IF(MOD(I22-H22,1)*24 >= 4, 0.5, 0))) | N22: =IF(OR(L22="", M22=""), "", MOD(M22-L22,1)*24 - IF(MOD(M22-L22,1)*24 >= 8, 1, IF(MOD(M22-L22,1)*24 >= 4, 0.5, 0))) | R22: =IF(OR(P22="", Q22=""), "", MOD(Q22-P22,1)*24 - IF(MOD(Q22-P22,1)*24 >= 8, 1, IF(MOD(Q22-P22,1)*24 >= 4, 0.5, 0))) | V22: =IF(OR(T22="", U22=""), "", MOD(U22-T22,1)*24 - IF(MOD(U22-T22,1)*24 >= 8, 1, IF(MOD(U22-T22,1)*24 >= 4, 0.5, 0))) | AN22: =IF(A22="", 0, WEEKNUM(A22, 2)) -> 8
A23: =IF(A22="","",IF(MONTH(A22+1)<>MONTH($A$3),"",A22+1)) -> 46074 | B23: =IF(A23="","",TEXT(A23, "aaa")) -> 토 | F23: =IF(OR(D23="", E23=""), "", MOD(E23-D23,1)*24 - IF(MOD(E23-D23,1)*24 >= 8, 1, IF(MOD(E23-D23,1)*24 >= 4, 0.5, 0))) | J23: =IF(OR(H23="", I23=""), "", MOD(I23-H23,1)*24 - IF(MOD(I23-H23,1)*24 >= 8, 1, IF(MOD(I23-H23,1)*24 >= 4, 0.5, 0))) | N23: =IF(OR(L23="", M23=""), "", MOD(M23-L23,1)*24 - IF(MOD(M23-L23,1)*24 >= 8, 1, IF(MOD(M23-L23,1)*24 >= 4, 0.5, 0))) | R23: =IF(OR(P23="", Q23=""), "", MOD(Q23-P23,1)*24 - IF(MOD(Q23-P23,1)*24 >= 8, 1, IF(MOD(Q23-P23,1)*24 >= 4, 0.5, 0))) | V23: =IF(OR(T23="", U23=""), "", MOD(U23-T23,1)*24 - IF(MOD(U23-T23,1)*24 >= 8, 1, IF(MOD(U23-T23,1)*24 >= 4, 0.5, 0))) | AN23: =IF(A23="", 0, WEEKNUM(A23, 2)) -> 8
A24: =IF(A23="","",IF(MONTH(A23+1)<>MONTH($A$3),"",A23+1)) -> 46075 | B24: =IF(A24="","",TEXT(A24, "aaa")) -> 일 | F24: =IF(OR(D24="", E24=""), "", MOD(E24-D24,1)*24 - IF(MOD(E24-D24,1)*24 >= 8, 1, IF(MOD(E24-D24,1)*24 >= 4, 0.5, 0))) | J24: =IF(OR(H24="", I24=""), "", MOD(I24-H24,1)*24 - IF(MOD(I24-H24,1)*24 >= 8, 1, IF(MOD(I24-H24,1)*24 >= 4, 0.5, 0))) | N24: =IF(OR(L24="", M24=""), "", MOD(M24-L24,1)*24 - IF(MOD(M24-L24,1)*24 >= 8, 1, IF(MOD(M24-L24,1)*24 >= 4, 0.5, 0))) | R24: =IF(OR(P24="", Q24=""), "", MOD(Q24-P24,1)*24 - IF(MOD(Q24-P24,1)*24 >= 8, 1, IF(MOD(Q24-P24,1)*24 >= 4, 0.5, 0))) | V24: =IF(OR(T24="", U24=""), "", MOD(U24-T24,1)*24 - IF(MOD(U24-T24,1)*24 >= 8, 1, IF(MOD(U24-T24,1)*24 >= 4, 0.5, 0))) | AN24: =IF(A24="", 0, WEEKNUM(A24, 2)) -> 8
A25: =IF(A24="","",IF(MONTH(A24+1)<>MONTH($A$3),"",A24+1)) -> 46076 | B25: =IF(A25="","",TEXT(A25, "aaa")) -> 월 | F25: =IF(OR(D25="", E25=""), "", MOD(E25-D25,1)*24 - IF(MOD(E25-D25,1)*24 >= 8, 1, IF(MOD(E25-D25,1)*24 >= 4, 0.5, 0))) | J25: =IF(OR(H25="", I25=""), "", MOD(I25-H25,1)*24 - IF(MOD(I25-H25,1)*24 >= 8, 1, IF(MOD(I25-H25,1)*24 >= 4, 0.5, 0))) | N25: =IF(OR(L25="", M25=""), "", MOD(M25-L25,1)*24 - IF(MOD(M25-L25,1)*24 >= 8, 1, IF(MOD(M25-L25,1)*24 >= 4, 0.5, 0))) | R25: =IF(OR(P25="", Q25=""), "", MOD(Q25-P25,1)*24 - IF(MOD(Q25-P25,1)*24 >= 8, 1, IF(MOD(Q25-P25,1)*24 >= 4, 0.5, 0))) | V25: =IF(OR(T25="", U25=""), "", MOD(U25-T25,1)*24 - IF(MOD(U25-T25,1)*24 >= 8, 1, IF(MOD(U25-T25,1)*24 >= 4, 0.5, 0))) | AN25: =IF(A25="", 0, WEEKNUM(A25, 2)) -> 9
A26: =IF(A25="","",IF(MONTH(A25+1)<>MONTH($A$3),"",A25+1)) -> 46077 | B26: =IF(A26="","",TEXT(A26, "aaa")) -> 화 | F26: =IF(OR(D26="", E26=""), "", MOD(E26-D26,1)*24 - IF(MOD(E26-D26,1)*24 >= 8, 1, IF(MOD(E26-D26,1)*24 >= 4, 0.5, 0))) | J26: =IF(OR(H26="", I26=""), "", MOD(I26-H26,1)*24 - IF(MOD(I26-H26,1)*24 >= 8, 1, IF(MOD(I26-H26,1)*24 >= 4, 0.5, 0))) | N26: =IF(OR(L26="", M26=""), "", MOD(M26-L26,1)*24 - IF(MOD(M26-L26,1)*24 >= 8, 1, IF(MOD(M26-L26,1)*24 >= 4, 0.5, 0))) | R26: =IF(OR(P26="", Q26=""), "", MOD(Q26-P26,1)*24 - IF(MOD(Q26-P26,1)*24 >= 8, 1, IF(MOD(Q26-P26,1)*24 >= 4, 0.5, 0))) | V26: =IF(OR(T26="", U26=""), "", MOD(U26-T26,1)*24 - IF(MOD(U26-T26,1)*24 >= 8, 1, IF(MOD(U26-T26,1)*24 >= 4, 0.5, 0))) | AN26: =IF(A26="", 0, WEEKNUM(A26, 2)) -> 9
A27: =IF(A26="","",IF(MONTH(A26+1)<>MONTH($A$3),"",A26+1)) -> 46078 | B27: =IF(A27="","",TEXT(A27, "aaa")) -> 수 | F27: =IF(OR(D27="", E27=""), "", MOD(E27-D27,1)*24 - IF(MOD(E27-D27,1)*24 >= 8, 1, IF(MOD(E27-D27,1)*24 >= 4, 0.5, 0))) | J27: =IF(OR(H27="", I27=""), "", MOD(I27-H27,1)*24 - IF(MOD(I27-H27,1)*24 >= 8, 1, IF(MOD(I27-H27,1)*24 >= 4, 0.5, 0))) | N27: =IF(OR(L27="", M27=""), "", MOD(M27-L27,1)*24 - IF(MOD(M27-L27,1)*24 >= 8, 1, IF(MOD(M27-L27,1)*24 >= 4, 0.5, 0))) | R27: =IF(OR(P27="", Q27=""), "", MOD(Q27-P27,1)*24 - IF(MOD(Q27-P27,1)*24 >= 8, 1, IF(MOD(Q27-P27,1)*24 >= 4, 0.5, 0))) | V27: =IF(OR(T27="", U27=""), "", MOD(U27-T27,1)*24 - IF(MOD(U27-T27,1)*24 >= 8, 1, IF(MOD(U27-T27,1)*24 >= 4, 0.5, 0))) | AN27: =IF(A27="", 0, WEEKNUM(A27, 2)) -> 9
A28: =IF(A27="","",IF(MONTH(A27+1)<>MONTH($A$3),"",A27+1)) -> 46079 | B28: =IF(A28="","",TEXT(A28, "aaa")) -> 목 | F28: =IF(OR(D28="", E28=""), "", MOD(E28-D28,1)*24 - IF(MOD(E28-D28,1)*24 >= 8, 1, IF(MOD(E28-D28,1)*24 >= 4, 0.5, 0))) | J28: =IF(OR(H28="", I28=""), "", MOD(I28-H28,1)*24 - IF(MOD(I28-H28,1)*24 >= 8, 1, IF(MOD(I28-H28,1)*24 >= 4, 0.5, 0))) | N28: =IF(OR(L28="", M28=""), "", MOD(M28-L28,1)*24 - IF(MOD(M28-L28,1)*24 >= 8, 1, IF(MOD(M28-L28,1)*24 >= 4, 0.5, 0))) | R28: =IF(OR(P28="", Q28=""), "", MOD(Q28-P28,1)*24 - IF(MOD(Q28-P28,1)*24 >= 8, 1, IF(MOD(Q28-P28,1)*24 >= 4, 0.5, 0))) | V28: =IF(OR(T28="", U28=""), "", MOD(U28-T28,1)*24 - IF(MOD(U28-T28,1)*24 >= 8, 1, IF(MOD(U28-T28,1)*24 >= 4, 0.5, 0))) | AN28: =IF(A28="", 0, WEEKNUM(A28, 2)) -> 9
... A33: =IF(A32="","",IF(MONTH(A32+1)<>MONTH($A$3),"",A32+1)) | B33: =IF(A33="","",TEXT(A33, "aaa")) | F33: =IF(OR(D33="", E33=""), "", MOD(E33-D33,1)*24 - IF(MOD(E33-D33,1)*24 >= 8, 1, IF(MOD(E33-D33,1)*24 >= 4, 0.5, 0))) | J33: =IF(OR(H33="", I33=""), "", MOD(I33-H33,1)*24 - IF(MOD(I33-H33,1)*24 >= 8, 1, IF(MOD(I33-H33,1)*24 >= 4, 0.5, 0))) | N33: =IF(OR(L33="", M33=""), "", MOD(M33-L33,1)*24 - IF(MOD(M33-L33,1)*24 >= 8, 1, IF(MOD(M33-L33,1)*24 >= 4, 0.5, 0))) | R33: =IF(OR(P33="", Q33=""), "", MOD(Q33-P33,1)*24 - IF(MOD(Q33-P33,1)*24 >= 8, 1, IF(MOD(Q33-P33,1)*24 >= 4, 0.5, 0))) | V33: =IF(OR(T33="", U33=""), "", MOD(U33-T33,1)*24 - IF(MOD(U33-T33,1)*24 >= 8, 1, IF(MOD(U33-T33,1)*24 >= 4, 0.5, 0))) | AN33: =IF(A33="", 0, WEEKNUM(A33, 2)) -> 0

Sheet 근무표(개인별종합)
A1: ='근무표(입력)'!Y3 -> 김도윤 | E1: ='근무표(입력)'!Y4 -> 김지수 | I1: ='근무표(입력)'!Y5 -> 김현호 | M1: ='근무표(입력)'!Y6 -> 송채민 | Q1: ='근무표(입력)'!Y7 -> 이예은 | U1: ='근무표(입력)'!Y8 -> 정가은 | Y1: ='근무표(입력)'!Y9 -> 황승연
A3: ='근무표(입력)'!A3 -> 46054 | B3: =TEXT(A3, "aaa") -> 일 | C3: =SUMIFS('근무표(입력)'!$F$3:$F$33, '근무표(입력)'!$C$3:$C$33, $A$1, '근무표(입력)'!$A$3:$A$33, $A3) + SUMIFS('근무표(입력)'!$J$3:$J$33, '근무표(입력)'!$G$3:$G$33, $A$1, '근무표(입력)'!$A$3:$A$33, $A3) + SUMIFS('근무표(입력)'!$N$3:$N$33, '근무표(입력)'!$K$3:$K$33, $A$1, '근무표(입력)'!$A$3:$A$33, $A3) + SUMIFS('근무표(입력)'!$R$3:$R$33, '근무표(입력)'!$O$3:$O$33, $A$1, '근무표(입력)'!$A$3:$A$33, $A3) -> 0 | E3: =A3 -> 46054 | F3: =TEXT(E3, "aaa") -> 일 | G3: =SUMIFS('근무표(입력)'!$F$3:$F$33, '근무표(입력)'!$C$3:$C$33, $E$1, '근무표(입력)'!$A$3:$A$33, $A3) + SUMIFS('근무표(입력)'!$J$3:$J$33, '근무표(입력)'!$G$3:$G$33, $E$1, '근무표(입력)'!$A$3:$A$33, $A3) + SUMIFS('근무표(입력)'!$N$3:$N$33, '근무표(입력)'!$K$3:$K$33, $E$1, '근무표(입력)'!$A$3:$A$33, $A3) + SUMIFS('근무표(입력)'!$R$3:$R$33, '근무표(입력)'!$O$3:$O$33, $E$1, '근무표(입력)'!$A$3:$A$33, $A3) -> 0 | I3: =A3 -> 46054 | J3: =TEXT(I3, "aaa") -> 일 | K3: =SUMIFS('근무표(입력)'!$F$3:$F$33, '근무표(입력)'!$C$3:$C$33, $I$1, '근무표(입력)'!$A$3:$A$33, $A3) + SUMIFS('근무표(입력)'!$J$3:$J$33, '근무표(입력)'!$G$3:$G$33, $I$1, '근무표(입력)'!$A$3:$A$33, $A3) + SUMIFS('근무표(입력)'!$N$3:$N$33, '근무표(입력)'!$K$3:$K$33, $I$1, '근무표(입력)'!$A$3:$A$33, $A3) + SUMIFS('근무표(입력)'!$R$3:$R$33, '근무표(입력)'!$O$3:$O$33, $I$1, '근무표(입력)'!$A$3:$A$33, $A3) -> 0 | M3: =A3 -> 46054 | N3: =TEXT(M3, "aaa") -> 일 | O3: =SUMIFS('근무표(입력)'!$F$3:$F$33, '근무표(입력)'!$C$3:$C$33, $M$1, '근무표(입력)'!$A$3:$A$33, $A3) + SUMIFS('근무표(입력)'!$J$3:$J$33, '근무표(입력)'!$G$3:$G$33, $M$1, '근무표(입력)'!$A$3:$A$33, $A3) + SUMIFS('근무표(입력)'!$N$3:$N$33, '근무표(입력)'!$K$3:$K$33, $M$1, '근무표(입력)'!$A$3:$A$33, $A3) + SUMIFS('근무표(입력)'!$R$3:$R$33, '근무표(입력)'!$O$3:$O$33, $M$1, '근무표(입력)'!$A$3:$A$33, $A3) -> 0 | Q3: =A3 -> 46054 | R3: =TEXT(Q3, "aaa") -> 일 | S3: =SUMIFS('근무표(입력)'!$F$3:$F$33, '근무표(입력)'!$C$3:$C$33, $Q$1, '근무표(입력)'!$A$3:$A$33, $A3) + SUMIFS('근무표(입력)'!$J$3:$J$33, '근무표(입력)'!$G$3:$G$33, $Q$1, '근무표(입력)'!$A$3:$A$33, $A3) + SUMIFS('근무표(입력)'!$N$3:$N$33, '근무표(입력)'!$K$3:$K$33, $Q$1, '근무표(입력)'!$A$3:$A$33, $A3) + SUMIFS('근무표(입력)'!$R$3:$R$33, '근무표(입력)'!$O$3:$O$33, $Q$1, '근무표(입력)'!$A$3:$A$33, $A3) -> 0 | U3: =A3 -> 46054 | V3: =TEXT(U3, "aaa") -> 일 | W3: =SUMIFS('근무표(입력)'!$F$3:$F$33, '근무표(입력)'!$C$3:$C$33, $U$1, '근무표(입력)'!$A$3:$A$33, $A3) + SUMIFS('근무표(입력)'!$J$3:$J$33, '근무표(입력)'!$G$3:$G$33, $U$1, '근무표(입력)'!$A$3:$A$33, $A3) + SUMIFS('근무표(입력)'!$N$3:$N$33, '근무표(입력)'!$K$3:$K$33, $U$1, '근무표(입력)'!$A$3:$A$33, $A3) + SUMIFS('근무표(입력)'!$R$3:$R$33, '근무표(입력)'!$O$3:$O$33, $U$1, '근무표(입력)'!$A$3:$A$33, $A3) -> 0 | Y3: =A3 -> 46054 | Z3: =TEXT(Y3, "aaa") -> 일 | AA3: =SUMIFS('근무표(입력)'!$F$3:$F$33, '근무표(입력)'!$C$3:$C$33, $Y$1, '근무표(입력)'!$A$3:$A$33, $A3) + SUMIFS('근무표(입력)'!$J$3:$J$33, '근무표(입력)'!$G$3:$G$33, $Y$1, '근무표(입력)'!$A$3:$A$33, $A3) + SUMIFS('근무표(입력)'!$N$3:$N$33, '근무표(입력)'!$K$3:$K$33, $Y$1, '근무표(입력)'!$A$3:$A$33, $A3) + SUMIFS('근무표(입력)'!$R$3:$R$33, '근무표(입력)'!$O$3:$O$33, $Y$1, '근무표(입력)'!$A$3:$A$33, $A3) -> 0
A4: =IF(A3="","",IF(MONTH(A3+1)<>MONTH($A$3),"",A3+1)) -> 46055 | B4: =IF(A4="","",TEXT(A4, "aaa")) -> 월 | C4: =SUMIFS('근무표(입력)'!$F$3:$F$33, '근무표(입력)'!$C$3:$C$33, $A$1, '근무표(입력)'!$A$3:$A$33, $A4) + SUMIFS('근무표(입력)'!$J$3:$J$33, '근무표(입력)'!$G$3:$G$33, $A$1, '근무표(입력)'!$A$3:$A$33, $A4) + SUMIFS('근무표(입력)'!$N$3:$N$33, '근무표(입력)'!$K$3:$K$33, $A$1, '근무표(입력)'!$A$3:$A$33, $A4) + SUMIFS('근무표(입력)'!$R$3:$R$33, '근무표(입력)'!$O$3:$O$33, $A$1, '근무표(입력)'!$A$3:$A$33, $A4) -> 0 | E4: =IF(E3="","",IF(MONTH(E3+1)<>MONTH($A$3),"",E3+1)) -> 46055 | F4: =IF(E4="","",TEXT(E4, "aaa")) -> 월 | G4: =SUMIFS('근무표(입력)'!$F$3:$F$33, '근무표(입력)'!$C$3:$C$33, $E$1, '근무표(입력)'!$A$3:$A$33, $A4) + SUMIFS('근무표(입력)'!$J$3:$J$33, '근무표(입력)'!$G$3:$G$33, $E$1, '근무표(입력)'!$A$3:$A$33, $A4) + SUMIFS('근무표(입력)'!$N$3:$N$33, '근무표(입력)'!$K$3:$K$33, $E$1, '근무표(입력)'!$A$3:$A$33, $A4) + SUMIFS('근무표(입력)'!$R$3:$R$33, '근무표(입력)'!$O$3:$O$33, $E$1, '근무표(입력)'!$A$3:$A$33, $A4) -> 0 | I4: =IF(I3="","",IF(MONTH(I3+1)<>MONTH($A$3),"",I3+1)) -> 46055 | J4: =IF(I4="","",TEXT(I4, "aaa")) -> 월 | K4: =SUMIFS('근무표(입력)'!$F$3:$F$33, '근무표(입력)'!$C$3:$C$33, $I$1, '근무표(입력)'!$A$3:$A$33, $A4) + SUMIFS('근무표(입력)'!$J$3:$J$33, '근무표(입력)'!$G$3:$G$33, $I$1, '근무표(입력)'!$A$3:$A$33, $A4) + SUMIFS('근무표(입력)'!$N$3:$N$33, '근무표(입력)'!$K$3:$K$33, $I$1, '근무표(입력)'!$A$3:$A$33, $A4) + SUMIFS('근무표(입력)'!$R$3:$R$33, '근무표(입력)'!$O$3:$O$33, $I$1, '근무표(입력)'!$A$3:$A$33, $A4) -> 0 | M4: =IF(M3="","",IF(MONTH(M3+1)<>MONTH($A$3),"",M3+1)) -> 46055 | N4: =IF(M4="","",TEXT(M4, "aaa")) -> 월 | O4: =SUMIFS('근무표(입력)'!$F$3:$F$33, '근무표(입력)'!$C$3:$C$33, $M$1, '근무표(입력)'!$A$3:$A$33, $A4) + SUMIFS('근무표(입력)'!$J$3:$J$33, '근무표(입력)'!$G$3:$G$33, $M$1, '근무표(입력)'!$A$3:$A$33, $A4) + SUMIFS('근무표(입력)'!$N$3:$N$33, '근무표(입력)'!$K$3:$K$33, $M$1, '근무표(입력)'!$A$3:$A$33, $A4) + SUMIFS('근무표(입력)'!$R$3:$R$33, '근무표(입력)'!$O$3:$O$33, $M$1, '근무표(입력)'!$A$3:$A$33, $A4) -> 0 | Q4: =IF(Q3="","",IF(MONTH(Q3+1)<>MONTH($A$3),"",Q3+1)) -> 46055 | R4: =IF(Q4="","",TEXT(Q4, "aaa")) -> 월 | S4: =SUMIFS('근무표(입력)'!$F$3:$F$33, '근무표(입력)'!$C$3:$C$33, $Q$1, '근무표(입력)'!$A$3:$A$33, $A4) + SUMIFS('근무표(입력)'!$J$3:$J$33, '근무표(입력)'!$G$3:$G$33, $Q$1, '근무표(입력)'!$A$3:$A$33, $A4) + SUMIFS('근무표(입력)'!$N$3:$N$33, '근무표(입력)'!$K$3:$K$33, $Q$1, '근무표(입력)'!$A$3:$A$33, $A4) + SUMIFS('근무표(입력)'!$R$3:$R$33, '근무표(입력)'!$O$3:$O$33, $Q$1, '근무표(입력)'!$A$3:$A$33, $A4) -> 0 | U4: =IF(U3="","",IF(MONTH(U3+1)<>MONTH($A$3),"",U3+1)) -> 46055 | V4: =IF(U4="","",TEXT(U4, "aaa")) -> 월 | W4: =SUMIFS('근무표(입력)'!$F$3:$F$33, '근무표(입력)'!$C$3:$C$33, $U$1, '근무표(입력)'!$A$3:$A$33, $A4) + SUMIFS('근무표(입력)'!$J$3:$J$33, '근무표(입력)'!$G$3:$G$33, $U$1, '근무표(입력)'!$A$3:$A$33, $A4) + SUMIFS('근무표(입력)'!$N$3:$N$33, '근무표(입력)'!$K$3:$K$33, $U$1, '근무표(입력)'!$A$3:$A$33, $A4) + SUMIFS('근무표(입력)'!$R$3:$R$33, '근무표(입력)'!$O$3:$O$33, $U$1, '근무표(입력)'!$A$3:$A$33, $A4) -> 0 | Y4: =IF(Y3="","",IF(MONTH(Y3+1)<>MONTH($A$3),"",Y3+1)) -> 46055 | Z4: =IF(Y4="","",TEXT(Y4, "aaa")) -> 월 | AA4: =SUMIFS('근무표(입력)'!$F$3:$F$33, '근무표(입력)'!$C$3:$C$33, $Y$1, '근무표(입력)'!$A$3:$A$33, $A4) + SUMIFS('근무표(입력)'!$J$3:$J$33, '근무표(입력)'!$G$3:$G$33, $Y$1, '근무표(입력)'!$A$3:$A$33, $A4) + SUMIFS('근무표(입력)'!$N$3:$N$33, '근무표(입력)'!$K$3:$K$33, $Y$1, '근무표(입력)'!$A$3:$A$33, $A4) + SUMIFS('근무표(입력)'!$R$3:$R$33, '근무표(입력)'!$O$3:$O$33, $Y$1, '근무표(입력)'!$A$3:$A$33, $A4) -> 0
A5: =IF(A4="","",IF(MONTH(A4+1)<>MONTH($A$3),"",A4+1)) -> 46056 | B5: =IF(A5="","",TEXT(A5, "aaa")) -> 화 | C5: =SUMIFS('근무표(입력)'!$F$3:$F$33, '근무표(입력)'!$C$3:$C$33, $A$1, '근무표(입력)'!$A$3:$A$33, $A5) + SUMIFS('근무표(입력)'!$J$3:$J$33, '근무표(입력)'!$G$3:$G$33, $A$1, '근무표(입력)'!$A$3:$A$33, $A5) + SUMIFS('근무표(입력)'!$N$3:$N$33, '근무표(입력)'!$K$3:$K$33, $A$1, '근무표(입력)'!$A$3:$A$33, $A5) + SUMIFS('근무표(입력)'!$R$3:$R$33, '근무표(입력)'!$O$3:$O$33, $A$1, '근무표(입력)'!$A$3:$A$33, $A5) -> 0 | E5: =IF(E4="","",IF(MONTH(E4+1)<>MONTH($A$3),"",E4+1)) -> 46056 | F5: =IF(E5="","",TEXT(E5, "aaa")) -> 화 | G5: =SUMIFS('근무표(입력)'!$F$3:$F$33, '근무표(입력)'!$C$3:$C$33, $E$1, '근무표(입력)'!$A$3:$A$33, $A5) + SUMIFS('근무표(입력)'!$J$3:$J$33, '근무표(입력)'!$G$3:$G$33, $E$1, '근무표(입력)'!$A$3:$A$33, $A5) + SUMIFS('근무표(입력)'!$N$3:$N$33, '근무표(입력)'!$K$3:$K$33, $E$1, '근무표(입력)'!$A$3:$A$33, $A5) + SUMIFS('근무표(입력)'!$R$3:$R$33, '근무표(입력)'!$O$3:$O$33, $E$1, '근무표(입력)'!$A$3:$A$33, $A5) -> 0 | I5: =IF(I4="","",IF(MONTH(I4+1)<>MONTH($A$3),"",I4+1)) -> 46056 | J5: =IF(I5="","",TEXT(I5, "aaa")) -> 화 | K5: =SUMIFS('근무표(입력)'!$F$3:$F$33, '근무표(입력)'!$C$3:$C$33, $I$1, '근무표(입력)'!$A$3:$A$33, $A5) + SUMIFS('근무표(입력)'!$J$3:$J$33, '근무표(입력)'!$G$3:$G$33, $I$1, '근무표(입력)'!$A$3:$A$33, $A5) + SUMIFS('근무표(입력)'!$N$3:$N$33, '근무표(입력)'!$K$3:$K$33, $I$1, '근무표(입력)'!$A$3:$A$33, $A5) + SUMIFS('근무표(입력)'!$R$3:$R$33, '근무표(입력)'!$O$3:$O$33, $I$1, '근무표(입력)'!$A$3:$A$33, $A5) -> 0 | M5: =IF(M4="","",IF(MONTH(M4+1)<>MONTH($A$3),"",M4+1)) -> 46056 | N5: =IF(M5="","",TEXT(M5, "aaa")) -> 화 | O5: =SUMIFS('근무표(입력)'!$F$3:$F$33, '근무표(입력)'!$C$3:$C$33, $M$1, '근무표(입력)'!$A$3:$A$33, $A5) + SUMIFS('근무표(입력)'!$J$3:$J$33, '근무표(입력)'!$G$3:$G$33, $M$1, '근무표(입력)'!$A$3:$A$33, $A5) + SUMIFS('근무표(입력)'!$N$3:$N$33, '근무표(입력)'!$K$3:$K$33, $M$1, '근무표(입력)'!$A$3:$A$33, $A5) + SUMIFS('근무표(입력)'!$R$3:$R$33, '근무표(입력)'!$O$3:$O$33, $M$1, '근무표(입력)'!$A$3:$A$33, $A5) -> 0 | Q5: =IF(Q4="","",IF(MONTH(Q4+1)<>MONTH($A$3),"",Q4+1)) -> 46056 | R5: =IF(Q5="","",TEXT(Q5, "aaa")) -> 화 | S5: =SUMIFS('근무표(입력)'!$F$3:$F$33, '근무표(입력)'!$C$3:$C$33, $Q$1, '근무표(입력)'!$A$3:$A$33, $A5) + SUMIFS('근무표(입력)'!$J$3:$J$33, '근무표(입력)'!$G$3:$G$33, $Q$1, '근무표(입력)'!$A$3:$A$33, $A5) + SUMIFS('근무표(입력)'!$N$3:$N$33, '근무표(입력)'!$K$3:$K$33, $Q$1, '근무표(입력)'!$A$3:$A$33, $A5) + SUMIFS('근무표(입력)'!$R$3:$R$33, '근무표(입력)'!$O$3:$O$33, $Q$1, '근무표(입력)'!$A$3:$A$33, $A5) -> 0 | U5: =IF(U4="","",IF(MONTH(U4+1)<>MONTH($A$3),"",U4+1)) -> 46056 | V5: =IF(U5="","",TEXT(U5, "aaa")) -> 화 | W5: =SUMIFS('근무표(입력)'!$F$3:$F$33, '근무표(입력)'!$C$3:$C$33, $U$1, '근무표(입력)'!$A$3:$A$33, $A5) + SUMIFS('근무표(입력)'!$J$3:$J$33, '근무표(입력)'!$G$3:$G$33, $U$1, '근무표(입력)'!$A$3:$A$33, $A5) + SUMIFS('근무표(입력)'!$N$3:$N$33, '근무표(입력)'!$K$3:$K$33, $U$1, '근무표(입력)'!$A$3:$A$33, $A5) + SUMIFS('근무표(입력)'!$R$3:$R$33, '근무표(입력)'!$O$3:$O$33, $U$1, '근무표(입력)'!$A$3:$A$33, $A5) -> 0 | Y5: =IF(Y4="","",IF(MONTH(Y4+1)<>MONTH($A$3),"",Y4+1)) -> 46056 | Z5: =IF(Y5="","",TEXT(Y5, "aaa")) -> 화 | AA5: =SUMIFS('근무표(입력)'!$F$3:$F$33, '근무표(입력)'!$C$3:$C$33, $Y$1, '근무표(입력)'!$A$3:$A$33, $A5) + SUMIFS('근무표(입력)'!$J$3:$J$33, '근무표(입력)'!$G$3:$G$33, $Y$1, '근무표(입력)'!$A$3:$A$33, $A5) + SUMIFS('근무표(입력)'!$N$3:$N$33, '근무표(입력)'!$K$3:$K$33, $Y$1, '근무표(입력)'!$A$3:$A$33, $A5) + SUMIFS('근무표(입력)'!$R$3:$R$33, '근무표(입력)'!$O$3:$O$33, $Y$1, '근무표(입력)'!$A$3:$A$33, $A5) -> 0
A6: =IF(A5="","",IF(MONTH(A5+1)<>MONTH($A$3),"",A5+1)) -> 46057 | B6: =IF(A6="","",TEXT(A6, "aaa")) -> 수 | C6: =SUMIFS('근무표(입력)'!$F$3:$F$33, '근무표(입력)'!$C$3:$C$33, $A$1, '근무표(입력)'!$A$3:$A$33, $A6) + SUMIFS('근무표(입력)'!$J$3:$J$33, '근무표(입력)'!$G$3:$G$33, $A$1, '근무표(입력)'!$A$3:$A$33, $A6) + SUMIFS('근무표(입력)'!$N$3:$N$33, '근무표(입력)'!$K$3:$K$33, $A$1, '근무표(입력)'!$A$3:$A$33, $A6) + SUMIFS('근무표(입력)'!$R$3:$R$33, '근무표(입력)'!$O$3:$O$33, $A$1, '근무표(입력)'!$A$3:$A$33, $A6) -> 0 | E6: =IF(E5="","",IF(MONTH(E5+1)<>MONTH($A$3),"",E5+1)) -> 46057 | F6: =IF(E6="","",TEXT(E6, "aaa")) -> 수 | G6: =SUMIFS('근무표(입력)'!$F$3:$F$33, '근무표(입력)'!$C$3:$C$33, $E$1, '근무표(입력)'!$A$3:$A$33, $A6) + SUMIFS('근무표(입력)'!$J$3:$J$33, '근무표(입력)'!$G$3:$G$33, $E$1, '근무표(입력)'!$A$3:$A$33, $A6) + SUMIFS('근무표(입력)'!$N$3:$N$33, '근무표(입력)'!$K$3:$K$33, $E$1, '근무표(입력)'!$A$3:$A$33, $A6) + SUMIFS('근무표(입력)'!$R$3:$R$33, '근무표(입력)'!$O$3:$O$33, $E$1, '근무표(입력)'!$A$3:$A$33, $A6) -> 0 | I6: =IF(I5="","",IF(MONTH(I5+1)<>MONTH($A$3),"",I5+1)) -> 46057 | J6: =IF(I6="","",TEXT(I6, "aaa")) -> 수 | K6: =SUMIFS('근무표(입력)'!$F$3:$F$33, '근무표(입력)'!$C$3:$C$33, $I$1, '근무표(입력)'!$A$3:$A$33, $A6) + SUMIFS('근무표(입력)'!$J$3:$J$33, '근무표(입력)'!$G$3:$G$33, $I$1, '근무표(입력)'!$A$3:$A$33, $A6) + SUMIFS('근무표(입력)'!$N$3:$N$33, '근무표(입력)'!$K$3:$K$33, $I$1, '근무표(입력)'!$A$3:$A$33, $A6) + SUMIFS('근무표(입력)'!$R$3:$R$33, '근무표(입력)'!$O$3:$O$33, $I$1, '근무표(입력)'!$A$3:$A$33, $A6) -> 0 | M6: =IF(M5="","",IF(MONTH(M5+1)<>MONTH($A$3),"",M5+1)) -> 46057 | N6: =IF(M6="","",TEXT(M6, "aaa")) -> 수 | O6: =SUMIFS('근무표(입력)'!$F$3:$F$33, '근무표(입력)'!$C$3:$C$33, $M$1, '근무표(입력)'!$A$3:$A$33, $A6) + SUMIFS('근무표(입력)'!$J$3:$J$33, '근무표(입력)'!$G$3:$G$33, $M$1, '근무표(입력)'!$A$3:$A$33, $A6) + SUMIFS('근무표(입력)'!$N$3:$N$33, '근무표(입력)'!$K$3:$K$33, $M$1, '근무표(입력)'!$A$3:$A$33, $A6) + SUMIFS('근무표(입력)'!$R$3:$R$33, '근무표(입력)'!$O$3:$O$33, $M$1, '근무표(입력)'!$A$3:$A$33, $A6) -> 0 | Q6: =IF(Q5="","",IF(MONTH(Q5+1)<>MONTH($A$3),"",Q5+1)) -> 46057 | R6: =IF(Q6="","",TEXT(Q6, "aaa")) -> 수 | S6: =SUMIFS('근무표(입력)'!$F$3:$F$33, '근무표(입력)'!$C$3:$C$33, $Q$1, '근무표(입력)'!$A$3:$A$33, $A6) + SUMIFS('근무표(입력)'!$J$3:$J$33, '근무표(입력)'!$G$3:$G$33, $Q$1, '근무표(입력)'!$A$3:$A$33, $A6) + SUMIFS('근무표(입력)'!$N$3:$N$33, '근무표(입력)'!$K$3:$K$33, $Q$1, '근무표(입력)'!$A$3:$A$33, $A6) + SUMIFS('근무표(입력)'!$R$3:$R$33, '근무표(입력)'!$O$3:$O$33, $Q$1, '근무표(입력)'!$A$3:$A$33, $A6) -> 0 | U6: =IF(U5="","",IF(MONTH(U5+1)<>MONTH($A$3),"",U5+1)) -> 46057 | V6: =IF(U6="","",TEXT(U6, "aaa")) -> 수 | W6: =SUMIFS('근무표(입력)'!$F$3:$F$33, '근무표(입력)'!$C$3:$C$33, $U$1, '근무표(입력)'!$A$3:$A$33, $A6) + SUMIFS('근무표(입력)'!$J$3:$J$33, '근무표(입력)'!$G$3:$G$33, $U$1, '근무표(입력)'!$A$3:$A$33, $A6) + SUMIFS('근무표(입력)'!$N$3:$N$33, '근무표(입력)'!$K$3:$K$33, $U$1, '근무표(입력)'!$A$3:$A$33, $A6) + SUMIFS('근무표(입력)'!$R$3:$R$33, '근무표(입력)'!$O$3:$O$33, $U$1, '근무표(입력)'!$A$3:$A$33, $A6) -> 0 | Y6: =IF(Y5="","",IF(MONTH(Y5+1)<>MONTH($A$3),"",Y5+1)) -> 46057 | Z6: =IF(Y6="","",TEXT(Y6, "aaa")) -> 수 | AA6: =SUMIFS('근무표(입력)'!$F$3:$F$33, '근무표(입력)'!$C$3:$C$33, $Y$1, '근무표(입력)'!$A$3:$A$33, $A6) + SUMIFS('근무표(입력)'!$J$3:$J$33, '근무표(입력)'!$G$3:$G$33, $Y$1, '근무표(입력)'!$A$3:$A$33, $A6) + SUMIFS('근무표(입력)'!$N$3:$N$33, '근무표(입력)'!$K$3:$K$33, $Y$1, '근무표(입력)'!$A$3:$A$33, $A6) + SUMIFS('근무표(입력)'!$R$3:$R$33, '근무표(입력)'!$O$3:$O$33, $Y$1, '근무표(입력)'!$A$3:$A$33, $A6) -> 0
A7: =IF(A6="","",IF(MONTH(A6+1)<>MONTH($A$3),"",A6+1)) -> 46058 | B7: =IF(A7="","",TEXT(A7, "aaa")) -> 목 | C7: =SUMIFS('근무표(입력)'!$F$3:$F$33, '근무표(입력)'!$C$3:$C$33, $A$1, '근무표(입력)'!$A$3:$A$33, $A7) + SUMIFS('근무표(입력)'!$J$3:$J$33, '근무표(입력)'!$G$3:$G$33, $A$1, '근무표(입력)'!$A$3:$A$33, $A7) + SUMIFS('근무표(입력)'!$N$3:$N$33, '근무표(입력)'!$K$3:$K$33, $A$1, '근무표(입력)'!$A$3:$A$33, $A7) + SUMIFS('근무표(입력)'!$R$3:$R$33, '근무표(입력)'!$O$3:$O$33, $A$1, '근무표(입력)'!$A$3:$A$33, $A7) -> 0 | E7: =IF(E6="","",IF(MONTH(E6+1)<>MONTH($A$3),"",E6+1)) -> 46058 | F7: =IF(E7="","",TEXT(E7, "aaa")) -> 목 | G7: =SUMIFS('근무표(입력)'!$F$3:$F$33, '근무표(입력)'!$C$3:$C$33, $E$1, '근무표(입력)'!$A$3:$A$33, $A7) + SUMIFS('근무표(입력)'!$J$3:$J$33, '근무표(입력)'!$G$3:$G$33, $E$1, '근무표(입력)'!$A$3:$A$33, $A7) + SUMIFS('근무표(입력)'!$N$3:$N$33, '근무표(입력)'!$K$3:$K$33, $E$1, '근무표(입력)'!$A$3:$A$33, $A7) + SUMIFS('근무표(입력)'!$R$3:$R$33, '근무표(입력)'!$O$3:$O$33, $E$1, '근무표(입력)'!$A$3:$A$33, $A7) -> 0 | I7: =IF(I6="","",IF(MONTH(I6+1)<>MONTH($A$3),"",I6+1)) -> 46058 | J7: =IF(I7="","",TEXT(I7, "aaa")) -> 목 | K7: =SUMIFS('근무표(입력)'!$F$3:$F$33, '근무표(입력)'!$C$3:$C$33, $I$1, '근무표(입력)'!$A$3:$A$33, $A7) + SUMIFS('근무표(입력)'!$J$3:$J$33, '근무표(입력)'!$G$3:$G$33, $I$1, '근무표(입력)'!$A$3:$A$33, $A7) + SUMIFS('근무표(입력)'!$N$3:$N$33, '근무표(입력)'!$K$3:$K$33, $I$1, '근무표(입력)'!$A$3:$A$33, $A7) + SUMIFS('근무표(입력)'!$R$3:$R$33, '근무표(입력)'!$O$3:$O$33, $I$1, '근무표(입력)'!$A$3:$A$33, $A7) -> 0 | M7: =IF(M6="","",IF(MONTH(M6+1)<>MONTH($A$3),"",M6+1)) -> 46058 | N7: =IF(M7="","",TEXT(M7, "aaa")) -> 목 | O7: =SUMIFS('근무표(입력)'!$F$3:$F$33, '근무표(입력)'!$C$3:$C$33, $M$1, '근무표(입력)'!$A$3:$A$33, $A7) + SUMIFS('근무표(입력)'!$J$3:$J$33, '근무표(입력)'!$G$3:$G$33, $M$1, '근무표(입력)'!$A$3:$A$33, $A7) + SUMIFS('근무표(입력)'!$N$3:$N$33, '근무표(입력)'!$K$3:$K$33, $M$1, '근무표(입력)'!$A$3:$A$33, $A7) + SUMIFS('근무표(입력)'!$R$3:$R$33, '근무표(입력)'!$O$3:$O$33, $M$1, '근무표(입력)'!$A$3:$A$33, $A7) -> 0 | Q7: =IF(Q6="","",IF(MONTH(Q6+1)<>MONTH($A$3),"",Q6+1)) -> 46058 | R7: =IF(Q7="","",TEXT(Q7, "aaa")) -> 목 | S7: =SUMIFS('근무표(입력)'!$F$3:$F$33, '근무표(입력)'!$C$3:$C$33, $Q$1, '근무표(입력)'!$A$3:$A$33, $A7) + SUMIFS('근무표(입력)'!$J$3:$J$33, '근무표(입력)'!$G$3:$G$33, $Q$1, '근무표(입력)'!$A$3:$A$33, $A7) + SUMIFS('근무표(입력)'!$N$3:$N$33, '근무표(입력)'!$K$3:$K$33, $Q$1, '근무표(입력)'!$A$3:$A$33, $A7) + SUMIFS('근무표(입력)'!$R$3:$R$33, '근무표(입력)'!$O$3:$O$33, $Q$1, '근무표(입력)'!$A$3:$A$33, $A7) -> 0 | U7: =IF(U6="","",IF(MONTH(U6+1)<>MONTH($A$3),"",U6+1)) -> 46058 | V7: =IF(U7="","",TEXT(U7, "aaa")) -> 목 | W7: =SUMIFS('근무표(입력)'!$F$3:$F$33, '근무표(입력)'!$C$3:$C$33, $U$1, '근무표(입력)'!$A$3:$A$33, $A7) + SUMIFS('근무표(입력)'!$J$3:$J$33, '근무표(입력)'!$G$3:$G$33, $U$1, '근무표(입력)'!$A$3:$A$33, $A7) + SUMIFS('근무표(입력)'!$N$3:$N$33, '근무표(입력)'!$K$3:$K$33, $U$1, '근무표(입력)'!$A$3:$A$33, $A7) + SUMIFS('근무표(입력)'!$R$3:$R$33, '근무표(입력)'!$O$3:$O$33, $U$1, '근무표(입력)'!$A$3:$A$33, $A7) -> 0 | Y7: =IF(Y6="","",IF(MONTH(Y6+1)<>MONTH($A$3),"",Y6+1)) -> 46058 | Z7: =IF(Y7="","",TEXT(Y7, "aaa")) -> 목 | AA7: =SUMIFS('근무표(입력)'!$F$3:$F$33, '근무표(입력)'!$C$3:$C$33, $Y$1, '근무표(입력)'!$A$3:$A$33, $A7) + SUMIFS('근무표(입력)'!$J$3:$J$33, '근무표(입력)'!$G$3:$G$33, $Y$1, '근무표(입력)'!$A$3:$A$33, $A7) + SUMIFS('근무표(입력)'!$N$3:$N$33, '근무표(입력)'!$K$3:$K$33, $Y$1, '근무표(입력)'!$A$3:$A$33, $A7) + SUMIFS('근무표(입력)'!$R$3:$R$33, '근무표(입력)'!$O$3:$O$33, $Y$1, '근무표(입력)'!$A$3:$A$33, $A7) -> 0
A8: =IF(A7="","",IF(MONTH(A7+1)<>MONTH($A$3),"",A7+1)) -> 46059 | B8: =IF(A8="","",TEXT(A8, "aaa")) -> 금 | C8: =SUMIFS('근무표(입력)'!$F$3:$F$33, '근무표(입력)'!$C$3:$C$33, $A$1, '근무표(입력)'!$A$3:$A$33, $A8) + SUMIFS('근무표(입력)'!$J$3:$J$33, '근무표(입력)'!$G$3:$G$33, $A$1, '근무표(입력)'!$A$3:$A$33, $A8) + SUMIFS('근무표(입력)'!$N$3:$N$33, '근무표(입력)'!$K$3:$K$33, $A$1, '근무표(입력)'!$A$3:$A$33, $A8) + SUMIFS('근무표(입력)'!$R$3:$R$33, '근무표(입력)'!$O$3:$O$33, $A$1, '근무표(입력)'!$A$3:$A$33, $A8) -> 0 | E8: =IF(E7="","",IF(MONTH(E7+1)<>MONTH($A$3),"",E7+1)) -> 46059 | F8: =IF(E8="","",TEXT(E8, "aaa")) -> 금 | G8: =SUMIFS('근무표(입력)'!$F$3:$F$33, '근무표(입력)'!$C$3:$C$33, $E$1, '근무표(입력)'!$A$3:$A$33, $A8) + SUMIFS('근무표(입력)'!$J$3:$J$33, '근무표(입력)'!$G$3:$G$33, $E$1, '근무표(입력)'!$A$3:$A$33, $A8) + SUMIFS('근무표(입력)'!$N$3:$N$33, '근무표(입력)'!$K$3:$K$33, $E$1, '근무표(입력)'!$A$3:$A$33, $A8) + SUMIFS('근무표(입력)'!$R$3:$R$33, '근무표(입력)'!$O$3:$O$33, $E$1, '근무표(입력)'!$A$3:$A$33, $A8) -> 0 | I8: =IF(I7="","",IF(MONTH(I7+1)<>MONTH($A$3),"",I7+1)) -> 46059 | J8: =IF(I8="","",TEXT(I8, "aaa")) -> 금 | K8: =SUMIFS('근무표(입력)'!$F$3:$F$33, '근무표(입력)'!$C$3:$C$33, $I$1, '근무표(입력)'!$A$3:$A$33, $A8) + SUMIFS('근무표(입력)'!$J$3:$J$33, '근무표(입력)'!$G$3:$G$33, $I$1, '근무표(입력)'!$A$3:$A$33, $A8) + SUMIFS('근무표(입력)'!$N$3:$N$33, '근무표(입력)'!$K$3:$K$33, $I$1, '근무표(입력)'!$A$3:$A$33, $A8) + SUMIFS('근무표(입력)'!$R$3:$R$33, '근무표(입력)'!$O$3:$O$33, $I$1, '근무표(입력)'!$A$3:$A$33, $A8) -> 0 | M8: =IF(M7="","",IF(MONTH(M7+1)<>MONTH($A$3),"",M7+1)) -> 46059 | N8: =IF(M8="","",TEXT(M8, "aaa")) -> 금 | O8: =SUMIFS('근무표(입력)'!$F$3:$F$33, '근무표(입력)'!$C$3:$C$33, $M$1, '근무표(입력)'!$A$3:$A$33, $A8) + SUMIFS('근무표(입력)'!$J$3:$J$33, '근무표(입력)'!$G$3:$G$33, $M$1, '근무표(입력)'!$A$3:$A$33, $A8) + SUMIFS('근무표(입력)'!$N$3:$N$33, '근무표(입력)'!$K$3:$K$33, $M$1, '근무표(입력)'!$A$3:$A$33, $A8) + SUMIFS('근무표(입력)'!$R$3:$R$33, '근무표(입력)'!$O$3:$O$33, $M$1, '근무표(입력)'!$A$3:$A$33, $A8) -> 0 | Q8: =IF(Q7="","",IF(MONTH(Q7+1)<>MONTH($A$3),"",Q7+1)) -> 46059 | R8: =IF(Q8="","",TEXT(Q8, "aaa")) -> 금 | S8: =SUMIFS('근무표(입력)'!$F$3:$F$33, '근무표(입력)'!$C$3:$C$33, $Q$1, '근무표(입력)'!$A$3:$A$33, $A8) + SUMIFS('근무표(입력)'!$J$3:$J$33, '근무표(입력)'!$G$3:$G$33, $Q$1, '근무표(입력)'!$A$3:$A$33, $A8) + SUMIFS('근무표(입력)'!$N$3:$N$33, '근무표(입력)'!$K$3:$K$33, $Q$1, '근무표(입력)'!$A$3:$A$33, $A8) + SUMIFS('근무표(입력)'!$R$3:$R$33, '근무표(입력)'!$O$3:$O$33, $Q$1, '근무표(입력)'!$A$3:$A$33, $A8) -> 0 | U8: =IF(U7="","",IF(MONTH(U7+1)<>MONTH($A$3),"",U7+1)) -> 46059 | V8: =IF(U8="","",TEXT(U8, "aaa")) -> 금 | W8: =SUMIFS('근무표(입력)'!$F$3:$F$33, '근무표(입력)'!$C$3:$C$33, $U$1, '근무표(입력)'!$A$3:$A$33, $A8) + SUMIFS('근무표(입력)'!$J$3:$J$33, '근무표(입력)'!$G$3:$G$33, $U$1, '근무표(입력)'!$A$3:$A$33, $A8) + SUMIFS('근무표(입력)'!$N$3:$N$33, '근무표(입력)'!$K$3:$K$33, $U$1, '근무표(입력)'!$A$3:$A$33, $A8) + SUMIFS('근무표(입력)'!$R$3:$R$33, '근무표(입력)'!$O$3:$O$33, $U$1, '근무표(입력)'!$A$3:$A$33, $A8) -> 0 | Y8: =IF(Y7="","",IF(MONTH(Y7+1)<>MONTH($A$3),"",Y7+1)) -> 46059 | Z8: =IF(Y8="","",TEXT(Y8, "aaa")) -> 금 | AA8: =SUMIFS('근무표(입력)'!$F$3:$F$33, '근무표(입력)'!$C$3:$C$33, $Y$1, '근무표(입력)'!$A$3:$A$33, $A8) + SUMIFS('근무표(입력)'!$J$3:$J$33, '근무표(입력)'!$G$3:$G$33, $Y$1, '근무표(입력)'!$A$3:$A$33, $A8) + SUMIFS('근무표(입력)'!$N$3:$N$33, '근무표(입력)'!$K$3:$K$33, $Y$1, '근무표(입력)'!$A$3:$A$33, $A8) + SUMIFS('근무표(입력)'!$R$3:$R$33, '근무표(입력)'!$O$3:$O$33, $Y$1, '근무표(입력)'!$A$3:$A$33, $A8) -> 0
A9: =IF(A8="","",IF(MONTH(A8+1)<>MONTH($A$3),"",A8+1)) -> 46060 | B9: =IF(A9="","",TEXT(A9, "aaa")) -> 토 | C9: =SUMIFS('근무표(입력)'!$F$3:$F$33, '근무표(입력)'!$C$3:$C$33, $A$1, '근무표(입력)'!$A$3:$A$33, $A9) + SUMIFS('근무표(입력)'!$J$3:$J$33, '근무표(입력)'!$G$3:$G$33, $A$1, '근무표(입력)'!$A$3:$A$33, $A9) + SUMIFS('근무표(입력)'!$N$3:$N$33, '근무표(입력)'!$K$3:$K$33, $A$1, '근무표(입력)'!$A$3:$A$33, $A9) + SUMIFS('근무표(입력)'!$R$3:$R$33, '근무표(입력)'!$O$3:$O$33, $A$1, '근무표(입력)'!$A$3:$A$33, $A9) -> 0 | E9: =IF(E8="","",IF(MONTH(E8+1)<>MONTH($A$3),"",E8+1)) -> 46060 | F9: =IF(E9="","",TEXT(E9, "aaa")) -> 토 | G9: =SUMIFS('근무표(입력)'!$F$3:$F$33, '근무표(입력)'!$C$3:$C$33, $E$1, '근무표(입력)'!$A$3:$A$33, $A9) + SUMIFS('근무표(입력)'!$J$3:$J$33, '근무표(입력)'!$G$3:$G$33, $E$1, '근무표(입력)'!$A$3:$A$33, $A9) + SUMIFS('근무표(입력)'!$N$3:$N$33, '근무표(입력)'!$K$3:$K$33, $E$1, '근무표(입력)'!$A$3:$A$33, $A9) + SUMIFS('근무표(입력)'!$R$3:$R$33, '근무표(입력)'!$O$3:$O$33, $E$1, '근무표(입력)'!$A$3:$A$33, $A9) -> 0 | I9: =IF(I8="","",IF(MONTH(I8+1)<>MONTH($A$3),"",I8+1)) -> 46060 | J9: =IF(I9="","",TEXT(I9, "aaa")) -> 토 | K9: =SUMIFS('근무표(입력)'!$F$3:$F$33, '근무표(입력)'!$C$3:$C$33, $I$1, '근무표(입력)'!$A$3:$A$33, $A9) + SUMIFS('근무표(입력)'!$J$3:$J$33, '근무표(입력)'!$G$3:$G$33, $I$1, '근무표(입력)'!$A$3:$A$33, $A9) + SUMIFS('근무표(입력)'!$N$3:$N$33, '근무표(입력)'!$K$3:$K$33, $I$1, '근무표(입력)'!$A$3:$A$33, $A9) + SUMIFS('근무표(입력)'!$R$3:$R$33, '근무표(입력)'!$O$3:$O$33, $I$1, '근무표(입력)'!$A$3:$A$33, $A9) -> 0 | M9: =IF(M8="","",IF(MONTH(M8+1)<>MONTH($A$3),"",M8+1)) -> 46060 | N9: =IF(M9="","",TEXT(M9, "aaa")) -> 토 | O9: =SUMIFS('근무표(입력)'!$F$3:$F$33, '근무표(입력)'!$C$3:$C$33, $M$1, '근무표(입력)'!$A$3:$A$33, $A9) + SUMIFS('근무표(입력)'!$J$3:$J$33, '근무표(입력)'!$G$3:$G$33, $M$1, '근무표(입력)'!$A$3:$A$33, $A9) + SUMIFS('근무표(입력)'!$N$3:$N$33, '근무표(입력)'!$K$3:$K$33, $M$1, '근무표(입력)'!$A$3:$A$33, $A9) + SUMIFS('근무표(입력)'!$R$3:$R$33, '근무표(입력)'!$O$3:$O$33, $M$1, '근무표(입력)'!$A$3:$A$33, $A9) -> 0 | Q9: =IF(Q8="","",IF(MONTH(Q8+1)<>MONTH($A$3),"",Q8+1)) -> 46060 | R9: =IF(Q9="","",TEXT(Q9, "aaa")) -> 토 | S9: =SUMIFS('근무표(입력)'!$F$3:$F$33, '근무표(입력)'!$C$3:$C$33, $Q$1, '근무표(입력)'!$A$3:$A$33, $A9) + SUMIFS('근무표(입력)'!$J$3:$J$33, '근무표(입력)'!$G$3:$G$33, $Q$1, '근무표(입력)'!$A$3:$A$33, $A9) + SUMIFS('근무표(입력)'!$N$3:$N$33, '근무표(입력)'!$K$3:$K$33, $Q$1, '근무표(입력)'!$A$3:$A$33, $A9) + SUMIFS('근무표(입력)'!$R$3:$R$33, '근무표(입력)'!$O$3:$O$33, $Q$1, '근무표(입력)'!$A$3:$A$33, $A9) -> 0 | U9: =IF(U8="","",IF(MONTH(U8+1)<>MONTH($A$3),"",U8+1)) -> 46060 | V9: =IF(U9="","",TEXT(U9, "aaa")) -> 토 | W9: =SUMIFS('근무표(입력)'!$F$3:$F$33, '근무표(입력)'!$C$3:$C$33, $U$1, '근무표(입력)'!$A$3:$A$33, $A9) + SUMIFS('근무표(입력)'!$J$3:$J$33, '근무표(입력)'!$G$3:$G$33, $U$1, '근무표(입력)'!$A$3:$A$33, $A9) + SUMIFS('근무표(입력)'!$N$3:$N$33, '근무표(입력)'!$K$3:$K$33, $U$1, '근무표(입력)'!$A$3:$A$33, $A9) + SUMIFS('근무표(입력)'!$R$3:$R$33, '근무표(입력)'!$O$3:$O$33, $U$1, '근무표(입력)'!$A$3:$A$33, $A9) -> 0 | Y9: =IF(Y8="","",IF(MONTH(Y8+1)<>MONTH($A$3),"",Y8+1)) -> 46060 | Z9: =IF(Y9="","",TEXT(Y9, "aaa")) -> 토 | AA9: =SUMIFS('근무표(입력)'!$F$3:$F$33, '근무표(입력)'!$C$3:$C$33, $Y$1, '근무표(입력)'!$A$3:$A$33, $A9) + SUMIFS('근무표(입력)'!$J$3:$J$33, '근무표(입력)'!$G$3:$G$33, $Y$1, '근무표(입력)'!$A$3:$A$33, $A9) + SUMIFS('근무표(입력)'!$N$3:$N$33, '근무표(입력)'!$K$3:$K$33, $Y$1, '근무표(입력)'!$A$3:$A$33, $A9) + SUMIFS('근무표(입력)'!$R$3:$R$33, '근무표(입력)'!$O$3:$O$33, $Y$1, '근무표(입력)'!$A$3:$A$33, $A9) -> 0
A10: =IF(A9="","",IF(MONTH(A9+1)<>MONTH($A$3),"",A9+1)) -> 46061 | B10: =IF(A10="","",TEXT(A10, "aaa")) -> 일 | C10: =SUMIFS('근무표(입력)'!$F$3:$F$33, '근무표(입력)'!$C$3:$C$33, $A$1, '근무표(입력)'!$A$3:$A$33, $A10) + SUMIFS('근무표(입력)'!$J$3:$J$33, '근무표(입력)'!$G$3:$G$33, $A$1, '근무표(입력)'!$A$3:$A$33, $A10) + SUMIFS('근무표(입력)'!$N$3:$N$33, '근무표(입력)'!$K$3:$K$33, $A$1, '근무표(입력)'!$A$3:$A$33, $A10) + SUMIFS('근무표(입력)'!$R$3:$R$33, '근무표(입력)'!$O$3:$O$33, $A$1, '근무표(입력)'!$A$3:$A$33, $A10) -> 0 | E10: =IF(E9="","",IF(MONTH(E9+1)<>MONTH($A$3),"",E9+1)) -> 46061 | F10: =IF(E10="","",TEXT(E10, "aaa")) -> 일 | G10: =SUMIFS('근무표(입력)'!$F$3:$F$33, '근무표(입력)'!$C$3:$C$33, $E$1, '근무표(입력)'!$A$3:$A$33, $A10) + SUMIFS('근무표(입력)'!$J$3:$J$33, '근무표(입력)'!$G$3:$G$33, $E$1, '근무표(입력)'!$A$3:$A$33, $A10) + SUMIFS('근무표(입력)'!$N$3:$N$33, '근무표(입력)'!$K$3:$K$33, $E$1, '근무표(입력)'!$A$3:$A$33, $A10) + SUMIFS('근무표(입력)'!$R$3:$R$33, '근무표(입력)'!$O$3:$O$33, $E$1, '근무표(입력)'!$A$3:$A$33, $A10) -> 0 | I10: =IF(I9="","",IF(MONTH(I9+1)<>MONTH($A$3),"",I9+1)) -> 46061 | J10: =IF(I10="","",TEXT(I10, "aaa")) -> 일 | K10: =SUMIFS('근무표(입력)'!$F$3:$F$33, '근무표(입력)'!$C$3:$C$33, $I$1, '근무표(입력)'!$A$3:$A$33, $A10) + SUMIFS('근무표(입력)'!$J$3:$J$33, '근무표(입력)'!$G$3:$G$33, $I$1, '근무표(입력)'!$A$3:$A$33, $A10) + SUMIFS('근무표(입력)'!$N$3:$N$33, '근무표(입력)'!$K$3:$K$33, $I$1, '근무표(입력)'!$A$3:$A$33, $A10) + SUMIFS('근무표(입력)'!$R$3:$R$33, '근무표(입력)'!$O$3:$O$33, $I$1, '근무표(입력)'!$A$3:$A$33, $A10) -> 0 | M10: =IF(M9="","",IF(MONTH(M9+1)<>MONTH($A$3),"",M9+1)) -> 46061 | N10: =IF(M10="","",TEXT(M10, "aaa")) -> 일 | O10: =SUMIFS('근무표(입력)'!$F$3:$F$33, '근무표(입력)'!$C$3:$C$33, $M$1, '근무표(입력)'!$A$3:$A$33, $A10) + SUMIFS('근무표(입력)'!$J$3:$J$33, '근무표(입력)'!$G$3:$G$33, $M$1, '근무표(입력)'!$A$3:$A$33, $A10) + SUMIFS('근무표(입력)'!$N$3:$N$33, '근무표(입력)'!$K$3:$K$33, $M$1, '근무표(입력)'!$A$3:$A$33, $A10) + SUMIFS('근무표(입력)'!$R$3:$R$33, '근무표(입력)'!$O$3:$O$33, $M$1, '근무표(입력)'!$A$3:$A$33, $A10) -> 0 | Q10: =IF(Q9="","",IF(MONTH(Q9+1)<>MONTH($A$3),"",Q9+1)) -> 46061 | R10: =IF(Q10="","",TEXT(Q10, "aaa")) -> 일 | S10: =SUMIFS('근무표(입력)'!$F$3:$F$33, '근무표(입력)'!$C$3:$C$33, $Q$1, '근무표(입력)'!$A$3:$A$33, $A10) + SUMIFS('근무표(입력)'!$J$3:$J$33, '근무표(입력)'!$G$3:$G$33, $Q$1, '근무표(입력)'!$A$3:$A$33, $A10) + SUMIFS('근무표(입력)'!$N$3:$N$33, '근무표(입력)'!$K$3:$K$33, $Q$1, '근무표(입력)'!$A$3:$A$33, $A10) + SUMIFS('근무표(입력)'!$R$3:$R$33, '근무표(입력)'!$O$3:$O$33, $Q$1, '근무표(입력)'!$A$3:$A$33, $A10) -> 0 | U10: =IF(U9="","",IF(MONTH(U9+1)<>MONTH($A$3),"",U9+1)) -> 46061 | V10: =IF(U10="","",TEXT(U10, "aaa")) -> 일 | W10: =SUMIFS('근무표(입력)'!$F$3:$F$33, '근무표(입력)'!$C$3:$C$33, $U$1, '근무표(입력)'!$A$3:$A$33, $A10) + SUMIFS('근무표(입력)'!$J$3:$J$33, '근무표(입력)'!$G$3:$G$33, $U$1, '근무표(입력)'!$A$3:$A$33, $A10) + SUMIFS('근무표(입력)'!$N$3:$N$33, '근무표(입력)'!$K$3:$K$33, $U$1, '근무표(입력)'!$A$3:$A$33, $A10) + SUMIFS('근무표(입력)'!$R$3:$R$33, '근무표(입력)'!$O$3:$O$33, $U$1, '근무표(입력)'!$A$3:$A$33, $A10) -> 0 | Y10: =IF(Y9="","",IF(MONTH(Y9+1)<>MONTH($A$3),"",Y9+1)) -> 46061 | Z10: =IF(Y10="","",TEXT(Y10, "aaa")) -> 일 | AA10: =SUMIFS('근무표(입력)'!$F$3:$F$33, '근무표(입력)'!$C$3:$C$33, $Y$1, '근무표(입력)'!$A$3:$A$33, $A10) + SUMIFS('근무표(입력)'!$J$3:$J$33, '근무표(입력)'!$G$3:$G$33, $Y$1, '근무표(입력)'!$A$3:$A$33, $A10) + SUMIFS('근무표(입력)'!$N$3:$N$33, '근무표(입력)'!$K$3:$K$33, $Y$1, '근무표(입력)'!$A$3:$A$33, $A10) + SUMIFS('근무표(입력)'!$R$3:$R$33, '근무표(입력)'!$O$3:$O$33, $Y$1, '근무표(입력)'!$A$3:$A$33, $A10) -> 0
A11: =IF(A10="","",IF(MONTH(A10+1)<>MONTH($A$3),"",A10+1)) -> 46062 | B11: =IF(A11="","",TEXT(A11, "aaa")) -> 월 | C11: =SUMIFS('근무표(입력)'!$F$3:$F$33, '근무표(입력)'!$C$3:$C$33, $A$1, '근무표(입력)'!$A$3:$A$33, $A11) + SUMIFS('근무표(입력)'!$J$3:$J$33, '근무표(입력)'!$G$3:$G$33, $A$1, '근무표(입력)'!$A$3:$A$33, $A11) + SUMIFS('근무표(입력)'!$N$3:$N$33, '근무표(입력)'!$K$3:$K$33, $A$1, '근무표(입력)'!$A$3:$A$33, $A11) + SUMIFS('근무표(입력)'!$R$3:$R$33, '근무표(입력)'!$O$3:$O$33, $A$1, '근무표(입력)'!$A$3:$A$33, $A11) -> 0 | E11: =IF(E10="","",IF(MONTH(E10+1)<>MONTH($A$3),"",E10+1)) -> 46062 | F11: =IF(E11="","",TEXT(E11, "aaa")) -> 월 | G11: =SUMIFS('근무표(입력)'!$F$3:$F$33, '근무표(입력)'!$C$3:$C$33, $E$1, '근무표(입력)'!$A$3:$A$33, $A11) + SUMIFS('근무표(입력)'!$J$3:$J$33, '근무표(입력)'!$G$3:$G$33, $E$1, '근무표(입력)'!$A$3:$A$33, $A11) + SUMIFS('근무표(입력)'!$N$3:$N$33, '근무표(입력)'!$K$3:$K$33, $E$1, '근무표(입력)'!$A$3:$A$33, $A11) + SUMIFS('근무표(입력)'!$R$3:$R$33, '근무표(입력)'!$O$3:$O$33, $E$1, '근무표(입력)'!$A$3:$A$33, $A11) -> 0 | I11: =IF(I10="","",IF(MONTH(I10+1)<>MONTH($A$3),"",I10+1)) -> 46062 | J11: =IF(I11="","",TEXT(I11, "aaa")) -> 월 | K11: =SUMIFS('근무표(입력)'!$F$3:$F$33, '근무표(입력)'!$C$3:$C$33, $I$1, '근무표(입력)'!$A$3:$A$33, $A11) + SUMIFS('근무표(입력)'!$J$3:$J$33, '근무표(입력)'!$G$3:$G$33, $I$1, '근무표(입력)'!$A$3:$A$33, $A11) + SUMIFS('근무표(입력)'!$N$3:$N$33, '근무표(입력)'!$K$3:$K$33, $I$1, '근무표(입력)'!$A$3:$A$33, $A11) + SUMIFS('근무표(입력)'!$R$3:$R$33, '근무표(입력)'!$O$3:$O$33, $I$1, '근무표(입력)'!$A$3:$A$33, $A11) -> 0 | M11: =IF(M10="","",IF(MONTH(M10+1)<>MONTH($A$3),"",M10+1)) -> 46062 | N11: =IF(M11="","",TEXT(M11, "aaa")) -> 월 | O11: =SUMIFS('근무표(입력)'!$F$3:$F$33, '근무표(입력)'!$C$3:$C$33, $M$1, '근무표(입력)'!$A$3:$A$33, $A11) + SUMIFS('근무표(입력)'!$J$3:$J$33, '근무표(입력)'!$G$3:$G$33, $M$1, '근무표(입력)'!$A$3:$A$33, $A11) + SUMIFS('근무표(입력)'!$N$3:$N$33, '근무표(입력)'!$K$3:$K$33, $M$1, '근무표(입력)'!$A$3:$A$33, $A11) + SUMIFS('근무표(입력)'!$R$3:$R$33, '근무표(입력)'!$O$3:$O$33, $M$1, '근무표(입력)'!$A$3:$A$33, $A11) -> 0 | Q11: =IF(Q10="","",IF(MONTH(Q10+1)<>MONTH($A$3),"",Q10+1)) -> 46062 | R11: =IF(Q11="","",TEXT(Q11, "aaa")) -> 월 | S11: =SUMIFS('근무표(입력)'!$F$3:$F$33, '근무표(입력)'!$C$3:$C$33, $Q$1, '근무표(입력)'!$A$3:$A$33, $A11) + SUMIFS('근무표(입력)'!$J$3:$J$33, '근무표(입력)'!$G$3:$G$33, $Q$1, '근무표(입력)'!$A$3:$A$33, $A11) + SUMIFS('근무표(입력)'!$N$3:$N$33, '근무표(입력)'!$K$3:$K$33, $Q$1, '근무표(입력)'!$A$3:$A$33, $A11) + SUMIFS('근무표(입력)'!$R$3:$R$33, '근무표(입력)'!$O$3:$O$33, $Q$1, '근무표(입력)'!$A$3:$A$33, $A11) -> 0 | U11: =IF(U10="","",IF(MONTH(U10+1)<>MONTH($A$3),"",U10+1)) -> 46062 | V11: =IF(U11="","",TEXT(U11, "aaa")) -> 월 | W11: =SUMIFS('근무표(입력)'!$F$3:$F$33, '근무표(입력)'!$C$3:$C$33, $U$1, '근무표(입력)'!$A$3:$A$33, $A11) + SUMIFS('근무표(입력)'!$J$3:$J$33, '근무표(입력)'!$G$3:$G$33, $U$1, '근무표(입력)'!$A$3:$A$33, $A11) + SUMIFS('근무표(입력)'!$N$3:$N$33, '근무표(입력)'!$K$3:$K$33, $U$1, '근무표(입력)'!$A$3:$A$33, $A11) + SUMIFS('근무표(입력)'!$R$3:$R$33, '근무표(입력)'!$O$3:$O$33, $U$1, '근무표(입력)'!$A$3:$A$33, $A11) -> 0 | Y11: =IF(Y10="","",IF(MONTH(Y10+1)<>MONTH($A$3),"",Y10+1)) -> 46062 | Z11: =IF(Y11="","",TEXT(Y11, "aaa")) -> 월 | AA11: =SUMIFS('근무표(입력)'!$F$3:$F$33, '근무표(입력)'!$C$3:$C$33, $Y$1, '근무표(입력)'!$A$3:$A$33, $A11) + SUMIFS('근무표(입력)'!$J$3:$J$33, '근무표(입력)'!$G$3:$G$33, $Y$1, '근무표(입력)'!$A$3:$A$33, $A11) + SUMIFS('근무표(입력)'!$N$3:$N$33, '근무표(입력)'!$K$3:$K$33, $Y$1, '근무표(입력)'!$A$3:$A$33, $A11) + SUMIFS('근무표(입력)'!$R$3:$R$33, '근무표(입력)'!$O$3:$O$33, $Y$1, '근무표(입력)'!$A$3:$A$33, $A11) -> 0
A12: =IF(A11="","",IF(MONTH(A11+1)<>MONTH($A$3),"",A11+1)) -> 46063 | B12: =IF(A12="","",TEXT(A12, "aaa")) -> 화 | C12: =SUMIFS('근무표(입력)'!$F$3:$F$33, '근무표(입력)'!$C$3:$C$33, $A$1, '근무표(입력)'!$A$3:$A$33, $A12) + SUMIFS('근무표(입력)'!$J$3:$J$33, '근무표(입력)'!$G$3:$G$33, $A$1, '근무표(입력)'!$A$3:$A$33, $A12) + SUMIFS('근무표(입력)'!$N$3:$N$33, '근무표(입력)'!$K$3:$K$33, $A$1, '근무표(입력)'!$A$3:$A$33, $A12) + SUMIFS('근무표(입력)'!$R$3:$R$33, '근무표(입력)'!$O$3:$O$33, $A$1, '근무표(입력)'!$A$3:$A$33, $A12) -> 0 | E12: =IF(E11="","",IF(MONTH(E11+1)<>MONTH($A$3),"",E11+1)) -> 46063 | F12: =IF(E12="","",TEXT(E12, "aaa")) -> 화 | G12: =SUMIFS('근무표(입력)'!$F$3:$F$33, '근무표(입력)'!$C$3:$C$33, $E$1, '근무표(입력)'!$A$3:$A$33, $A12) + SUMIFS('근무표(입력)'!$J$3:$J$33, '근무표(입력)'!$G$3:$G$33, $E$1, '근무표(입력)'!$A$3:$A$33, $A12) + SUMIFS('근무표(입력)'!$N$3:$N$33, '근무표(입력)'!$K$3:$K$33, $E$1, '근무표(입력)'!$A$3:$A$33, $A12) + SUMIFS('근무표(입력)'!$R$3:$R$33, '근무표(입력)'!$O$3:$O$33, $E$1, '근무표(입력)'!$A$3:$A$33, $A12) -> 0 | I12: =IF(I11="","",IF(MONTH(I11+1)<>MONTH($A$3),"",I11+1)) -> 46063 | J12: =IF(I12="","",TEXT(I12, "aaa")) -> 화 | K12: =SUMIFS('근무표(입력)'!$F$3:$F$33, '근무표(입력)'!$C$3:$C$33, $I$1, '근무표(입력)'!$A$3:$A$33, $A12) + SUMIFS('근무표(입력)'!$J$3:$J$33, '근무표(입력)'!$G$3:$G$33, $I$1, '근무표(입력)'!$A$3:$A$33, $A12) + SUMIFS('근무표(입력)'!$N$3:$N$33, '근무표(입력)'!$K$3:$K$33, $I$1, '근무표(입력)'!$A$3:$A$33, $A12) + SUMIFS('근무표(입력)'!$R$3:$R$33, '근무표(입력)'!$O$3:$O$33, $I$1, '근무표(입력)'!$A$3:$A$33, $A12) -> 0 | M12: =IF(M11="","",IF(MONTH(M11+1)<>MONTH($A$3),"",M11+1)) -> 46063 | N12: =IF(M12="","",TEXT(M12, "aaa")) -> 화 | O12: =SUMIFS('근무표(입력)'!$F$3:$F$33, '근무표(입력)'!$C$3:$C$33, $M$1, '근무표(입력)'!$A$3:$A$33, $A12) + SUMIFS('근무표(입력)'!$J$3:$J$33, '근무표(입력)'!$G$3:$G$33, $M$1, '근무표(입력)'!$A$3:$A$33, $A12) + SUMIFS('근무표(입력)'!$N$3:$N$33, '근무표(입력)'!$K$3:$K$33, $M$1, '근무표(입력)'!$A$3:$A$33, $A12) + SUMIFS('근무표(입력)'!$R$3:$R$33, '근무표(입력)'!$O$3:$O$33, $M$1, '근무표(입력)'!$A$3:$A$33, $A12) -> 0 | Q12: =IF(Q11="","",IF(MONTH(Q11+1)<>MONTH($A$3),"",Q11+1)) -> 46063 | R12: =IF(Q12="","",TEXT(Q12, "aaa")) -> 화 | S12: =SUMIFS('근무표(입력)'!$F$3:$F$33, '근무표(입력)'!$C$3:$C$33, $Q$1, '근무표(입력)'!$A$3:$A$33, $A12) + SUMIFS('근무표(입력)'!$J$3:$J$33, '근무표(입력)'!$G$3:$G$33, $Q$1, '근무표(입력)'!$A$3:$A$33, $A12) + SUMIFS('근무표(입력)'!$N$3:$N$33, '근무표(입력)'!$K$3:$K$33, $Q$1, '근무표(입력)'!$A$3:$A$33, $A12) + SUMIFS('근무표(입력)'!$R$3:$R$33, '근무표(입력)'!$O$3:$O$33, $Q$1, '근무표(입력)'!$A$3:$A$33, $A12) -> 0 | U12: =IF(U11="","",IF(MONTH(U11+1)<>MONTH($A$3),"",U11+1)) -> 46063 | V12: =IF(U12="","",TEXT(U12, "aaa")) -> 화 | W12: =SUMIFS('근무표(입력)'!$F$3:$F$33, '근무표(입력)'!$C$3:$C$33, $U$1, '근무표(입력)'!$A$3:$A$33, $A12) + SUMIFS('근무표(입력)'!$J$3:$J$33, '근무표(입력)'!$G$3:$G$33, $U$1, '근무표(입력)'!$A$3:$A$33, $A12) + SUMIFS('근무표(입력)'!$N$3:$N$33, '근무표(입력)'!$K$3:$K$33, $U$1, '근무표(입력)'!$A$3:$A$33, $A12) + SUMIFS('근무표(입력)'!$R$3:$R$33, '근무표(입력)'!$O$3:$O$33, $U$1, '근무표(입력)'!$A$3:$A$33, $A12) -> 0 | Y12: =IF(Y11="","",IF(MONTH(Y11+1)<>MONTH($A$3),"",Y11+1)) -> 46063 | Z12: =IF(Y12="","",TEXT(Y12, "aaa")) -> 화 | AA12: =SUMIFS('근무표(입력)'!$F$3:$F$33, '근무표(입력)'!$C$3:$C$33, $Y$1, '근무표(입력)'!$A$3:$A$33, $A12) + SUMIFS('근무표(입력)'!$J$3:$J$33, '근무표(입력)'!$G$3:$G$33, $Y$1, '근무표(입력)'!$A$3:$A$33, $A12) + SUMIFS('근무표(입력)'!$N$3:$N$33, '근무표(입력)'!$K$3:$K$33, $Y$1, '근무표(입력)'!$A$3:$A$33, $A12) + SUMIFS('근무표(입력)'!$R$3:$R$33, '근무표(입력)'!$O$3:$O$33, $Y$1, '근무표(입력)'!$A$3:$A$33, $A12) -> 0
